Workbook

Sheet 📄 Завдання
A1: Домашнє завдання: RFM + Когортний аналіз
B3: КОНТЕКСТ
B4: Ви — аналітик у SaaS-продукті. Кожен користувач проходить через 7-денний безкоштовний тріал, після чого частина конвертується у платну підписку $19.99/місяць. Підписка продовжується автоматично щомісяця, поки клієнт не скасує. Юзери приходять з 5 каналів трафіку.
B6: Ваше завдання — проаналізувати базу платних клієнтів двома методами:
B7: 1. RFM — сегментувати клієнтів за їхньою поведінкою у підписці
B8: 2. Когортний аналіз — порівняти retention і LTV між когортами за місяцем реєстрації
B10: ДАНІ У ФАЙЛІ
B11: 📋 Реєстрації — список клієнтів з датою реєстрації, каналом, країною (тільки платні)
B12: 📋 Транзакції — історія усіх транзакцій клієнтів (тріал + місячна підписка), одна транзакція = один рядок
B13: 💸 Маркетинг — витрати на рекламу по каналам і місяцям (для бонусного завдання)
B15: ЩО ЗРОБИТИ
B17: КРОК 1 — Заповніть аркуш 👥 Клієнти - унікальні клієнти з інформацією по ним
B18: Для кожного клієнта порахуйте формулами:
... B59: • Загальний LTV/CAC по всьому платному маркетингу — чи інвестуємо в рекламу прибутково?

Sheet 📋 Реєстрації
A2: 📋 Реєстрації
A4: user_id | B4: signup_date | C4: country | D4: channel
A5: U0206 | B5: 45292 | C5: PL | D5: Google Ads
A6: U0209 | B6: 45292 | C6: FR | D6: Facebook Ads
A7: U0516 | B7: 45293 | C7: DE | D7: TikTok Ads
A8: U0245 | B8: 45294 | C8: UK | D8: Referral
A9: U0291 | B9: 45294 | C9: US | D9: Organic
A10: U0408 | B10: 45294 | C10: UA | D10: Google Ads
A11: U0883 | B11: 45294 | C11: US | D11: TikTok Ads
A12: U0333 | B12: 45295 | C12: UK | D12: Organic
A13: U0172 | B13: 45300 | C13: PL | D13: Organic
A14: U0641 | B14: 45300 | C14: US | D14: Facebook Ads
A15: U0879 | B15: 45300 | C15: PL | D15: Organic
A16: U0238 | B16: 45304 | C16: PL | D16: Google Ads
... A606: U0679 | B606: 45740 | C606: UK | D606: Facebook Ads

Sheet 📋 Транзакції
A2: 📋 Транзакції
A4: subscription_id | B4: user_id | C4: start_date | D4: end_date | E4: plan_type | F4: amount_usd | G4: status
A5: S00928 | B5: U0206 | C5: 45292 | D5: 45299 | E5: trial | F5: 0 | G5: ended
A6: S00947 | B6: U0209 | C6: 45292 | D6: 45299 | E6: trial | F6: 0 | G6: ended
A7: S02285 | B7: U0516 | C7: 45293 | D7: 45300 | E7: trial | F7: 0 | G7: ended
A8: S01115 | B8: U0245 | C8: 45294 | D8: 45301 | E8: trial | F8: 0 | G8: ended
A9: S01295 | B9: U0291 | C9: 45294 | D9: 45301 | E9: trial | F9: 0 | G9: ended
A10: S01820 | B10: U0408 | C10: 45294 | D10: 45301 | E10: trial | F10: 0 | G10: ended
A11: S03817 | B11: U0883 | C11: 45294 | D11: 45301 | E11: trial | F11: 0 | G11: ended
A12: S01495 | B12: U0333 | C12: 45295 | D12: 45302 | E12: trial | F12: 0 | G12: ended
A13: S00929 | B13: U0206 | C13: 45299 | D13: 45329 | E13: monthly | F13: 19.99 | G13: ended
A14: S00948 | B14: U0209 | C14: 45299 | D14: 45329 | E14: monthly | F14: 19.99 | G14: ended
A15: S00804 | B15: U0172 | C15: 45300 | D15: 45307 | E15: trial | F15: 0 | G15: ended
A16: S02286 | B16: U0516 | C16: 45300 | D16: 45330 | E16: monthly | F16: 19.99 | G16: ended
... A3623: S03788 | B3623: U0877 | C3623: 45747 | D3623: 45777 | E3623: monthly | F3623: 19.99 | G3623: active

Sheet 💸 Маркетинг
A2: 💸 Маркетингові витрати по каналах і місяцях
A4: month | B4: channel | C4: spend_usd
A5: 2024-01 | B5: Google Ads | C5: 619.89
A6: 2024-01 | B6: Facebook Ads | C6: 396.17
A7: 2024-01 | B7: TikTok Ads | C7: 554.84
A8: 2024-02 | B8: Google Ads | C8: 576.77
A9: 2024-02 | B9: Facebook Ads | C9: 523.05
A10: 2024-02 | B10: TikTok Ads | C10: 662.34
A11: 2024-03 | B11: Google Ads | C11: 741
A12: 2024-03 | B12: Facebook Ads | C12: 451.01
A13: 2024-03 | B13: TikTok Ads | C13: 647.47
A14: 2024-04 | B14: Google Ads | C14: 598.68
A15: 2024-04 | B15: Facebook Ads | C15: 495.52
A16: 2024-04 | B16: TikTok Ads | C16: 698.12
... A49: 2025-03 | B49: TikTok Ads | C49: 935.99

Sheet 👥 Клієнти
A1: 45747 | B1: ← Snapshot date
A2: 👥 Клієнти — список унікальних платящих користувачів + агрегати
G3: Активність у М+N (1 = був у підписці у цей місяць, 0 = ні) | S3: Виручка у М+N ($)
A4: User ID | B4: First Payment | C4: Cohort Month | D4: Paid Months | E4: Total Revenue ($) | F4: Recency (міс) | G4: М+0 | H4: М+1 | I4: М+2 | J4: М+3 | K4: М+4 | L4: М+5 | M4: М+6 | N4: М+7 | O4: М+8 | P4: М+9 | Q4: М+10 | R4: М+11 | S4: $M+0 | T4: $M+1 | U4: $M+2 | V4: $M+3 | W4: $M+4 | X4: $M+5 | Y4: $M+6 | Z4: $M+7 | AA4: $M+8 | AB4: $M+9 | AC4: $M+10 | AD4: $M+11
A5: ='📋 Реєстрації'!A5:A606 -> U0206 | B5: {=INDEX('📋 Транзакції'!$C$5:$C$3623,MATCH(A5,'📋 Транзакції'!$B$5:$B$3623,0))} -> 45292 | C5: =TEXT(B5,"YYYY-MM") -> 2024-01 | D5: =COUNTIF('📋 Транзакції'!$B$5:$B$3623,A5) -> 4 | E5: =SUMIF('📋 Транзакції'!$B$5:$B$3623,A5,'📋 Транзакції'!$F$5:$F$3623) -> 59.97 | F5: =INT($A$1-MAXIFS('📋 Транзакції'!$C$5:$C$3623,'📋 Транзакції'!$B$5:$B$3623,A5)) -> 388 | G5: =IF(COUNTIFS('📋 Транзакції'!$B$5:$B$3623,A5,'📋 Транзакції'!$C$5:$C$3623,">="&EDATE(DATEVALUE(C5&"-01"),0),'📋 Транзакції'!$C$5:$C$3623,"<"&EDATE(DATEVALUE(C5&"-01"),1))>0,1,0) -> 1 | H5: =IF(COUNTIFS('📋 Транзакції'!$B$5:$B$3623,A5,'📋 Транзакції'!$C$5:$C$3623,">="&EDATE(DATEVALUE(C5&"-01"),1),'📋 Транзакції'!$C$5:$C$3623,"<"&EDATE(DATEVALUE(C5&"-01"),2))>0,1,0) -> 1 | I5: =IF(COUNTIFS('📋 Транзакції'!$B$5:$B$3623,A5,'📋 Транзакції'!$C$5:$C$3623,">="&EDATE(DATEVALUE(C5&"-01"),2),'📋 Транзакції'!$C$5:$C$3623,"<"&EDATE(DATEVALUE(C5&"-01"),3))>0,1,0) -> 1 | J5: =IF(COUNTIFS('📋 Транзакції'!$B$5:$B$3623,A5,'📋 Транзакції'!$C$5:$C$3623,">="&EDATE(DATEVALUE(C5&"-01"),3),'📋 Транзакції'!$C$5:$C$3623,"<"&EDATE(DATEVALUE(C5&"-01"),4))>0,1,0) -> 0 | K5: =IF(COUNTIFS('📋 Транзакції'!$B$5:$B$3623,A5,'📋 Транзакції'!$C$5:$C$3623,">="&EDATE(DATEVALUE(C5&"-01"),4),'📋 Транзакції'!$C$5:$C$3623,"<"&EDATE(DATEVALUE(C5&"-01"),5))>0,1,0) -> 0 | L5: =IF(COUNTIFS('📋 Транзакції'!$B$5:$B$3623,A5,'📋 Транзакції'!$C$5:$C$3623,">="&EDATE(DATEVALUE(C5&"-01"),5),'📋 Транзакції'!$C$5:$C$3623,"<"&EDATE(DATEVALUE(C5&"-01"),6))>0,1,0) -> 0 | M5: =IF(COUNTIFS('📋 Транзакції'!$B$5:$B$3623,A5,'📋 Транзакції'!$C$5:$C$3623,">="&EDATE(DATEVALUE(C5&"-01"),6),'📋 Транзакції'!$C$5:$C$3623,"<"&EDATE(DATEVALUE(C5&"-01"),7))>0,1,0) -> 0 | N5: =IF(COUNTIFS('📋 Транзакції'!$B$5:$B$3623,A5,'📋 Транзакції'!$C$5:$C$3623,">="&EDATE(DATEVALUE(C5&"-01"),7),'📋 Транзакції'!$C$5:$C$3623,"<"&EDATE(DATEVALUE(C5&"-01"),8))>0,1,0) -> 0 | O5: =IF(COUNTIFS('📋 Транзакції'!$B$5:$B$3623,A5,'📋 Транзакції'!$C$5:$C$3623,">="&EDATE(DATEVALUE(C5&"-01"),8),'📋 Транзакції'!$C$5:$C$3623,"<"&EDATE(DATEVALUE(C5&"-01"),9))>0,1,0) -> 0 | P5: =IF(COUNTIFS('📋 Транзакції'!$B$5:$B$3623,A5,'📋 Транзакції'!$C$5:$C$3623,">="&EDATE(DATEVALUE(C5&"-01"),9),'📋 Транзакції'!$C$5:$C$3623,"<"&EDATE(DATEVALUE(C5&"-01"),10))>0,1,0) -> 0 | Q5: =IF(COUNTIFS('📋 Транзакції'!$B$5:$B$3623,A5,'📋 Транзакції'!$C$5:$C$3623,">="&EDATE(DATEVALUE(C5&"-01"),10),'📋 Транзакції'!$C$5:$C$3623,"<"&EDATE(DATEVALUE(C5&"-01"),11))>0,1,0) -> 0 | R5: =IF(COUNTIFS('📋 Транзакції'!$B$5:$B$3623,A5,'📋 Транзакції'!$C$5:$C$3623,">="&EDATE(DATEVALUE(C5&"-01"),11),'📋 Транзакції'!$C$5:$C$3623,"<"&EDATE(DATEVALUE(C5&"-01"),12))>0,1,0) -> 0 | S5: =SUMIFS('📋 Транзакції'!$F$5:$F$3623,'📋 Транзакції'!$B$5:$B$3623,A5,'📋 Транзакції'!$C$5:$C$3623,">="&EDATE(DATEVALUE(C5&"-01"),0),'📋 Транзакції'!$C$5:$C$3623,"<"&EDATE(DATEVALUE(C5&"-01"),1)) -> 19.99 | T5: =SUMIFS('📋 Транзакції'!$F$5:$F$3623,'📋 Транзакції'!$B$5:$B$3623,A5,'📋 Транзакції'!$C$5:$C$3623,">="&EDATE(DATEVALUE(C5&"-01"),1),'📋 Транзакції'!$C$5:$C$3623,"<"&EDATE(DATEVALUE(C5&"-01"),2)) -> 19.99 | U5: =SUMIFS('📋 Транзакції'!$F$5:$F$3623,'📋 Транзакції'!$B$5:$B$3623,A5,'📋 Транзакції'!$C$5:$C$3623,">="&EDATE(DATEVALUE(C5&"-01"),2),'📋 Транзакції'!$C$5:$C$3623,"<"&EDATE(DATEVALUE(C5&"-01"),3)) -> 19.99 | V5: =SUMIFS('📋 Транзакції'!$F$5:$F$3623,'📋 Транзакції'!$B$5:$B$3623,A5,'📋 Транзакції'!$C$5:$C$3623,">="&EDATE(DATEVALUE(C5&"-01"),3),'📋 Транзакції'!$C$5:$C$3623,"<"&EDATE(DATEVALUE(C5&"-01"),4)) -> 0 | W5: =SUMIFS('📋 Транзакції'!$F$5:$F$3623,'📋 Транзакції'!$B$5:$B$3623,A5,'📋 Транзакції'!$C$5:$C$3623,">="&EDATE(DATEVALUE(C5&"-01"),4),'📋 Транзакції'!$C$5:$C$3623,"<"&EDATE(DATEVALUE(C5&"-01"),5)) -> 0 | X5: =SUMIFS('📋 Транзакції'!$F$5:$F$3623,'📋 Транзакції'!$B$5:$B$3623,A5,'📋 Транзакції'!$C$5:$C$3623,">="&EDATE(DATEVALUE(C5&"-01"),5),'📋 Транзакції'!$C$5:$C$3623,"<"&EDATE(DATEVALUE(C5&"-01"),6)) -> 0 | Y5: =SUMIFS('📋 Транзакції'!$F$5:$F$3623,'📋 Транзакції'!$B$5:$B$3623,A5,'📋 Транзакції'!$C$5:$C$3623,">="&EDATE(DATEVALUE(C5&"-01"),6),'📋 Транзакції'!$C$5:$C$3623,"<"&EDATE(DATEVALUE(C5&"-01"),7)) -> 0 | Z5: =SUMIFS('📋 Транзакції'!$F$5:$F$3623,'📋 Транзакції'!$B$5:$B$3623,A5,'📋 Транзакції'!$C$5:$C$3623,">="&EDATE(DATEVALUE(C5&"-01"),7),'📋 Транзакції'!$C$5:$C$3623,"<"&EDATE(DATEVALUE(C5&"-01"),8)) -> 0 | AA5: =SUMIFS('📋 Транзакції'!$F$5:$F$3623,'📋 Транзакції'!$B$5:$B$3623,A5,'📋 Транзакції'!$C$5:$C$3623,">="&EDATE(DATEVALUE(C5&"-01"),8),'📋 Транзакції'!$C$5:$C$3623,"<"&EDATE(DATEVALUE(C5&"-01"),9)) -> 0 | AB5: =SUMIFS('📋 Транзакції'!$F$5:$F$3623,'📋 Транзакції'!$B$5:$B$3623,A5,'📋 Транзакції'!$C$5:$C$3623,">="&EDATE(DATEVALUE(C5&"-01"),9),'📋 Транзакції'!$C$5:$C$3623,"<"&EDATE(DATEVALUE(C5&"-01"),10)) -> 0 | AC5: =SUMIFS('📋 Транзакції'!$F$5:$F$3623,'📋 Транзакції'!$B$5:$B$3623,A5,'📋 Транзакції'!$C$5:$C$3623,">="&EDATE(DATEVALUE(C5&"-01"),10),'📋 Транзакції'!$C$5:$C$3623,"<"&EDATE(DATEVALUE(C5&"-01"),11)) -> 0 | AD5: =SUMIFS('📋 Транзакції'!$F$5:$F$3623,'📋 Транзакції'!$B$5:$B$3623,A5,'📋 Транзакції'!$C$5:$C$3623,">="&EDATE(DATEVALUE(C5&"-01"),11),'📋 Транзакції'!$C$5:$C$3623,"<"&EDATE(DATEVALUE(C5&"-01"),12)) -> 0
A6: ='📋 Реєстрації'!A6:A607 -> U0209 | B6: {=INDEX('📋 Транзакції'!$C$5:$C$3623,MATCH(A6,'📋 Транзакції'!$B$5:$B$3623,0))} -> 45292 | C6: =TEXT(B6,"YYYY-MM") -> 2024-01 | D6: =COUNTIF('📋 Транзакції'!$B$5:$B$3623,A6) -> 16 | E6: =SUMIF('📋 Транзакції'!$B$5:$B$3623,A6,'📋 Транзакції'!$F$5:$F$3623) -> 299.85 | F6: =INT($A$1-MAXIFS('📋 Транзакції'!$C$5:$C$3623,'📋 Транзакції'!$B$5:$B$3623,A6)) -> 28 | G6: =IF(COUNTIFS('📋 Транзакції'!$B$5:$B$3623,A6,'📋 Транзакції'!$C$5:$C$3623,">="&EDATE(DATEVALUE(C6&"-01"),0),'📋 Транзакції'!$C$5:$C$3623,"<"&EDATE(DATEVALUE(C6&"-01"),1))>0,1,0) -> 1 | H6: =IF(COUNTIFS('📋 Транзакції'!$B$5:$B$3623,A6,'📋 Транзакції'!$C$5:$C$3623,">="&EDATE(DATEVALUE(C6&"-01"),1),'📋 Транзакції'!$C$5:$C$3623,"<"&EDATE(DATEVALUE(C6&"-01"),2))>0,1,0) -> 1 | I6: =IF(COUNTIFS('📋 Транзакції'!$B$5:$B$3623,A6,'📋 Транзакції'!$C$5:$C$3623,">="&EDATE(DATEVALUE(C6&"-01"),2),'📋 Транзакції'!$C$5:$C$3623,"<"&EDATE(DATEVALUE(C6&"-01"),3))>0,1,0) -> 1 | J6: =IF(COUNTIFS('📋 Транзакції'!$B$5:$B$3623,A6,'📋 Транзакції'!$C$5:$C$3623,">="&EDATE(DATEVALUE(C6&"-01"),3),'📋 Транзакції'!$C$5:$C$3623,"<"&EDATE(DATEVALUE(C6&"-01"),4))>0,1,0) -> 1 | K6: =IF(COUNTIFS('📋 Транзакції'!$B$5:$B$3623,A6,'📋 Транзакції'!$C$5:$C$3623,">="&EDATE(DATEVALUE(C6&"-01"),4),'📋 Транзакції'!$C$5:$C$3623,"<"&EDATE(DATEVALUE(C6&"-01"),5))>0,1,0) -> 1 | L6: =IF(COUNTIFS('📋 Транзакції'!$B$5:$B$3623,A6,'📋 Транзакції'!$C$5:$C$3623,">="&EDATE(DATEVALUE(C6&"-01"),5),'📋 Транзакції'!$C$5:$C$3623,"<"&EDATE(DATEVALUE(C6&"-01"),6))>0,1,0) -> 1 | M6: =IF(COUNTIFS('📋 Транзакції'!$B$5:$B$3623,A6,'📋 Транзакції'!$C$5:$C$3623,">="&EDATE(DATEVALUE(C6&"-01"),6),'📋 Транзакції'!$C$5:$C$3623,"<"&EDATE(DATEVALUE(C6&"-01"),7))>0,1,0) -> 1 | N6: =IF(COUNTIFS('📋 Транзакції'!$B$5:$B$3623,A6,'📋 Транзакції'!$C$5:$C$3623,">="&EDATE(DATEVALUE(C6&"-01"),7),'📋 Транзакції'!$C$5:$C$3623,"<"&EDATE(DATEVALUE(C6&"-01"),8))>0,1,0) -> 1 | O6: =IF(COUNTIFS('📋 Транзакції'!$B$5:$B$3623,A6,'📋 Транзакції'!$C$5:$C$3623,">="&EDATE(DATEVALUE(C6&"-01"),8),'📋 Транзакції'!$C$5:$C$3623,"<"&EDATE(DATEVALUE(C6&"-01"),9))>0,1,0) -> 1 | P6: =IF(COUNTIFS('📋 Транзакції'!$B$5:$B$3623,A6,'📋 Транзакції'!$C$5:$C$3623,">="&EDATE(DATEVALUE(C6&"-01"),9),'📋 Транзакції'!$C$5:$C$3623,"<"&EDATE(DATEVALUE(C6&"-01"),10))>0,1,0) -> 1 | Q6: =IF(COUNTIFS('📋 Транзакції'!$B$5:$B$3623,A6,'📋 Транзакції'!$C$5:$C$3623,">="&EDATE(DATEVALUE(C6&"-01"),10),'📋 Транзакції'!$C$5:$C$3623,"<"&EDATE(DATEVALUE(C6&"-01"),11))>0,1,0) -> 1 | R6: =IF(COUNTIFS('📋 Транзакції'!$B$5:$B$3623,A6,'📋 Транзакції'!$C$5:$C$3623,">="&EDATE(DATEVALUE(C6&"-01"),11),'📋 Транзакції'!$C$5:$C$3623,"<"&EDATE(DATEVALUE(C6&"-01"),12))>0,1,0) -> 1 | S6: =SUMIFS('📋 Транзакції'!$F$5:$F$3623,'📋 Транзакції'!$B$5:$B$3623,A6,'📋 Транзакції'!$C$5:$C$3623,">="&EDATE(DATEVALUE(C6&"-01"),0),'📋 Транзакції'!$C$5:$C$3623,"<"&EDATE(DATEVALUE(C6&"-01"),1)) -> 19.99 | T6: =SUMIFS('📋 Транзакції'!$F$5:$F$3623,'📋 Транзакції'!$B$5:$B$3623,A6,'📋 Транзакції'!$C$5:$C$3623,">="&EDATE(DATEVALUE(C6&"-01"),1),'📋 Транзакції'!$C$5:$C$3623,"<"&EDATE(DATEVALUE(C6&"-01"),2)) -> 19.99 | U6: =SUMIFS('📋 Транзакції'!$F$5:$F$3623,'📋 Транзакції'!$B$5:$B$3623,A6,'📋 Транзакції'!$C$5:$C$3623,">="&EDATE(DATEVALUE(C6&"-01"),2),'📋 Транзакції'!$C$5:$C$3623,"<"&EDATE(DATEVALUE(C6&"-01"),3)) -> 19.99 | V6: =SUMIFS('📋 Транзакції'!$F$5:$F$3623,'📋 Транзакції'!$B$5:$B$3623,A6,'📋 Транзакції'!$C$5:$C$3623,">="&EDATE(DATEVALUE(C6&"-01"),3),'📋 Транзакції'!$C$5:$C$3623,"<"&EDATE(DATEVALUE(C6&"-01"),4)) -> 19.99 | W6: =SUMIFS('📋 Транзакції'!$F$5:$F$3623,'📋 Транзакції'!$B$5:$B$3623,A6,'📋 Транзакції'!$C$5:$C$3623,">="&EDATE(DATEVALUE(C6&"-01"),4),'📋 Транзакції'!$C$5:$C$3623,"<"&EDATE(DATEVALUE(C6&"-01"),5)) -> 19.99 | X6: =SUMIFS('📋 Транзакції'!$F$5:$F$3623,'📋 Транзакції'!$B$5:$B$3623,A6,'📋 Транзакції'!$C$5:$C$3623,">="&EDATE(DATEVALUE(C6&"-01"),5),'📋 Транзакції'!$C$5:$C$3623,"<"&EDATE(DATEVALUE(C6&"-01"),6)) -> 19.99 | Y6: =SUMIFS('📋 Транзакції'!$F$5:$F$3623,'📋 Транзакції'!$B$5:$B$3623,A6,'📋 Транзакції'!$C$5:$C$3623,">="&EDATE(DATEVALUE(C6&"-01"),6),'📋 Транзакції'!$C$5:$C$3623,"<"&EDATE(DATEVALUE(C6&"-01"),7)) -> 19.99 | Z6: =SUMIFS('📋 Транзакції'!$F$5:$F$3623,'📋 Транзакції'!$B$5:$B$3623,A6,'📋 Транзакції'!$C$5:$C$3623,">="&EDATE(DATEVALUE(C6&"-01"),7),'📋 Транзакції'!$C$5:$C$3623,"<"&EDATE(DATEVALUE(C6&"-01"),8)) -> 19.99 | AA6: =SUMIFS('📋 Транзакції'!$F$5:$F$3623,'📋 Транзакції'!$B$5:$B$3623,A6,'📋 Транзакції'!$C$5:$C$3623,">="&EDATE(DATEVALUE(C6&"-01"),8),'📋 Транзакції'!$C$5:$C$3623,"<"&EDATE(DATEVALUE(C6&"-01"),9)) -> 19.99 | AB6: =SUMIFS('📋 Транзакції'!$F$5:$F$3623,'📋 Транзакції'!$B$5:$B$3623,A6,'📋 Транзакції'!$C$5:$C$3623,">="&EDATE(DATEVALUE(C6&"-01"),9),'📋 Транзакції'!$C$5:$C$3623,"<"&EDATE(DATEVALUE(C6&"-01"),10)) -> 19.99 | AC6: =SUMIFS('📋 Транзакції'!$F$5:$F$3623,'📋 Транзакції'!$B$5:$B$3623,A6,'📋 Транзакції'!$C$5:$C$3623,">="&EDATE(DATEVALUE(C6&"-01"),10),'📋 Транзакції'!$C$5:$C$3623,"<"&EDATE(DATEVALUE(C6&"-01"),11)) -> 19.99 | AD6: =SUMIFS('📋 Транзакції'!$F$5:$F$3623,'📋 Транзакції'!$B$5:$B$3623,A6,'📋 Транзакції'!$C$5:$C$3623,">="&EDATE(DATEVALUE(C6&"-01"),11),'📋 Транзакції'!$C$5:$C$3623,"<"&EDATE(DATEVALUE(C6&"-01"),12)) -> 19.99
A7: ='📋 Реєстрації'!A7:A608 -> U0516 | B7: {=INDEX('📋 Транзакції'!$C$5:$C$3623,MATCH(A7,'📋 Транзакції'!$B$5:$B$3623,0))} -> 45293 | C7: =TEXT(B7,"YYYY-MM") -> 2024-01 | D7: =COUNTIF('📋 Транзакції'!$B$5:$B$3623,A7) -> 7 | E7: =SUMIF('📋 Транзакції'!$B$5:$B$3623,A7,'📋 Транзакції'!$F$5:$F$3623) -> 119.94 | F7: =INT($A$1-MAXIFS('📋 Транзакції'!$C$5:$C$3623,'📋 Транзакції'!$B$5:$B$3623,A7)) -> 297 | G7: =IF(COUNTIFS('📋 Транзакції'!$B$5:$B$3623,A7,'📋 Транзакції'!$C$5:$C$3623,">="&EDATE(DATEVALUE(C7&"-01"),0),'📋 Транзакції'!$C$5:$C$3623,"<"&EDATE(DATEVALUE(C7&"-01"),1))>0,1,0) -> 1 | H7: =IF(COUNTIFS('📋 Транзакції'!$B$5:$B$3623,A7,'📋 Транзакції'!$C$5:$C$3623,">="&EDATE(DATEVALUE(C7&"-01"),1),'📋 Транзакції'!$C$5:$C$3623,"<"&EDATE(DATEVALUE(C7&"-01"),2))>0,1,0) -> 1 | I7: =IF(COUNTIFS('📋 Транзакції'!$B$5:$B$3623,A7,'📋 Транзакції'!$C$5:$C$3623,">="&EDATE(DATEVALUE(C7&"-01"),2),'📋 Транзакції'!$C$5:$C$3623,"<"&EDATE(DATEVALUE(C7&"-01"),3))>0,1,0) -> 1 | J7: =IF(COUNTIFS('📋 Транзакції'!$B$5:$B$3623,A7,'📋 Транзакції'!$C$5:$C$3623,">="&EDATE(DATEVALUE(C7&"-01"),3),'📋 Транзакції'!$C$5:$C$3623,"<"&EDATE(DATEVALUE(C7&"-01"),4))>0,1,0) -> 1 | K7: =IF(COUNTIFS('📋 Транзакції'!$B$5:$B$3623,A7,'📋 Транзакції'!$C$5:$C$3623,">="&EDATE(DATEVALUE(C7&"-01"),4),'📋 Транзакції'!$C$5:$C$3623,"<"&EDATE(DATEVALUE(C7&"-01"),5))>0,1,0) -> 1 | L7: =IF(COUNTIFS('📋 Транзакції'!$B$5:$B$3623,A7,'📋 Транзакції'!$C$5:$C$3623,">="&EDATE(DATEVALUE(C7&"-01"),5),'📋 Транзакції'!$C$5:$C$3623,"<"&EDATE(DATEVALUE(C7&"-01"),6))>0,1,0) -> 1 | M7: =IF(COUNTIFS('📋 Транзакції'!$B$5:$B$3623,A7,'📋 Транзакції'!$C$5:$C$3623,">="&EDATE(DATEVALUE(C7&"-01"),6),'📋 Транзакції'!$C$5:$C$3623,"<"&EDATE(DATEVALUE(C7&"-01"),7))>0,1,0) -> 0 | N7: =IF(COUNTIFS('📋 Транзакції'!$B$5:$B$3623,A7,'📋 Транзакції'!$C$5:$C$3623,">="&EDATE(DATEVALUE(C7&"-01"),7),'📋 Транзакції'!$C$5:$C$3623,"<"&EDATE(DATEVALUE(C7&"-01"),8))>0,1,0) -> 0 | O7: =IF(COUNTIFS('📋 Транзакції'!$B$5:$B$3623,A7,'📋 Транзакції'!$C$5:$C$3623,">="&EDATE(DATEVALUE(C7&"-01"),8),'📋 Транзакції'!$C$5:$C$3623,"<"&EDATE(DATEVALUE(C7&"-01"),9))>0,1,0) -> 0 | P7: =IF(COUNTIFS('📋 Транзакції'!$B$5:$B$3623,A7,'📋 Транзакції'!$C$5:$C$3623,">="&EDATE(DATEVALUE(C7&"-01"),9),'📋 Транзакції'!$C$5:$C$3623,"<"&EDATE(DATEVALUE(C7&"-01"),10))>0,1,0) -> 0 | Q7: =IF(COUNTIFS('📋 Транзакції'!$B$5:$B$3623,A7,'📋 Транзакції'!$C$5:$C$3623,">="&EDATE(DATEVALUE(C7&"-01"),10),'📋 Транзакції'!$C$5:$C$3623,"<"&EDATE(DATEVALUE(C7&"-01"),11))>0,1,0) -> 0 | R7: =IF(COUNTIFS('📋 Транзакції'!$B$5:$B$3623,A7,'📋 Транзакції'!$C$5:$C$3623,">="&EDATE(DATEVALUE(C7&"-01"),11),'📋 Транзакції'!$C$5:$C$3623,"<"&EDATE(DATEVALUE(C7&"-01"),12))>0,1,0) -> 0 | S7: =SUMIFS('📋 Транзакції'!$F$5:$F$3623,'📋 Транзакції'!$B$5:$B$3623,A7,'📋 Транзакції'!$C$5:$C$3623,">="&EDATE(DATEVALUE(C7&"-01"),0),'📋 Транзакції'!$C$5:$C$3623,"<"&EDATE(DATEVALUE(C7&"-01"),1)) -> 19.99 | T7: =SUMIFS('📋 Транзакції'!$F$5:$F$3623,'📋 Транзакції'!$B$5:$B$3623,A7,'📋 Транзакції'!$C$5:$C$3623,">="&EDATE(DATEVALUE(C7&"-01"),1),'📋 Транзакції'!$C$5:$C$3623,"<"&EDATE(DATEVALUE(C7&"-01"),2)) -> 19.99 | U7: =SUMIFS('📋 Транзакції'!$F$5:$F$3623,'📋 Транзакції'!$B$5:$B$3623,A7,'📋 Транзакції'!$C$5:$C$3623,">="&EDATE(DATEVALUE(C7&"-01"),2),'📋 Транзакції'!$C$5:$C$3623,"<"&EDATE(DATEVALUE(C7&"-01"),3)) -> 19.99 | V7: =SUMIFS('📋 Транзакції'!$F$5:$F$3623,'📋 Транзакції'!$B$5:$B$3623,A7,'📋 Транзакції'!$C$5:$C$3623,">="&EDATE(DATEVALUE(C7&"-01"),3),'📋 Транзакції'!$C$5:$C$3623,"<"&EDATE(DATEVALUE(C7&"-01"),4)) -> 19.99 | W7: =SUMIFS('📋 Транзакції'!$F$5:$F$3623,'📋 Транзакції'!$B$5:$B$3623,A7,'📋 Транзакції'!$C$5:$C$3623,">="&EDATE(DATEVALUE(C7&"-01"),4),'📋 Транзакції'!$C$5:$C$3623,"<"&EDATE(DATEVALUE(C7&"-01"),5)) -> 19.99 | X7: =SUMIFS('📋 Транзакції'!$F$5:$F$3623,'📋 Транзакції'!$B$5:$B$3623,A7,'📋 Транзакції'!$C$5:$C$3623,">="&EDATE(DATEVALUE(C7&"-01"),5),'📋 Транзакції'!$C$5:$C$3623,"<"&EDATE(DATEVALUE(C7&"-01"),6)) -> 19.99 | Y7: =SUMIFS('📋 Транзакції'!$F$5:$F$3623,'📋 Транзакції'!$B$5:$B$3623,A7,'📋 Транзакції'!$C$5:$C$3623,">="&EDATE(DATEVALUE(C7&"-01"),6),'📋 Транзакції'!$C$5:$C$3623,"<"&EDATE(DATEVALUE(C7&"-01"),7)) -> 0 | Z7: =SUMIFS('📋 Транзакції'!$F$5:$F$3623,'📋 Транзакції'!$B$5:$B$3623,A7,'📋 Транзакції'!$C$5:$C$3623,">="&EDATE(DATEVALUE(C7&"-01"),7),'📋 Транзакції'!$C$5:$C$3623,"<"&EDATE(DATEVALUE(C7&"-01"),8)) -> 0 | AA7: =SUMIFS('📋 Транзакції'!$F$5:$F$3623,'📋 Транзакції'!$B$5:$B$3623,A7,'📋 Транзакції'!$C$5:$C$3623,">="&EDATE(DATEVALUE(C7&"-01"),8),'📋 Транзакції'!$C$5:$C$3623,"<"&EDATE(DATEVALUE(C7&"-01"),9)) -> 0 | AB7: =SUMIFS('📋 Транзакції'!$F$5:$F$3623,'📋 Транзакції'!$B$5:$B$3623,A7,'📋 Транзакції'!$C$5:$C$3623,">="&EDATE(DATEVALUE(C7&"-01"),9),'📋 Транзакції'!$C$5:$C$3623,"<"&EDATE(DATEVALUE(C7&"-01"),10)) -> 0 | AC7: =SUMIFS('📋 Транзакції'!$F$5:$F$3623,'📋 Транзакції'!$B$5:$B$3623,A7,'📋 Транзакції'!$C$5:$C$3623,">="&EDATE(DATEVALUE(C7&"-01"),10),'📋 Транзакції'!$C$5:$C$3623,"<"&EDATE(DATEVALUE(C7&"-01"),11)) -> 0 | AD7: =SUMIFS('📋 Транзакції'!$F$5:$F$3623,'📋 Транзакції'!$B$5:$B$3623,A7,'📋 Транзакції'!$C$5:$C$3623,">="&EDATE(DATEVALUE(C7&"-01"),11),'📋 Транзакції'!$C$5:$C$3623,"<"&EDATE(DATEVALUE(C7&"-01"),12)) -> 0
A8: ='📋 Реєстрації'!A8:A609 -> U0245 | B8: {=INDEX('📋 Транзакції'!$C$5:$C$3623,MATCH(A8,'📋 Транзакції'!$B$5:$B$3623,0))} -> 45294 | C8: =TEXT(B8,"YYYY-MM") -> 2024-01 | D8: =COUNTIF('📋 Транзакції'!$B$5:$B$3623,A8) -> 3 | E8: =SUMIF('📋 Транзакції'!$B$5:$B$3623,A8,'📋 Транзакції'!$F$5:$F$3623) -> 39.98 | F8: =INT($A$1-MAXIFS('📋 Транзакції'!$C$5:$C$3623,'📋 Транзакції'!$B$5:$B$3623,A8)) -> 416 | G8: =IF(COUNTIFS('📋 Транзакції'!$B$5:$B$3623,A8,'📋 Транзакції'!$C$5:$C$3623,">="&EDATE(DATEVALUE(C8&"-01"),0),'📋 Транзакції'!$C$5:$C$3623,"<"&EDATE(DATEVALUE(C8&"-01"),1))>0,1,0) -> 1 | H8: =IF(COUNTIFS('📋 Транзакції'!$B$5:$B$3623,A8,'📋 Транзакції'!$C$5:$C$3623,">="&EDATE(DATEVALUE(C8&"-01"),1),'📋 Транзакції'!$C$5:$C$3623,"<"&EDATE(DATEVALUE(C8&"-01"),2))>0,1,0) -> 1 | I8: =IF(COUNTIFS('📋 Транзакції'!$B$5:$B$3623,A8,'📋 Транзакції'!$C$5:$C$3623,">="&EDATE(DATEVALUE(C8&"-01"),2),'📋 Транзакції'!$C$5:$C$3623,"<"&EDATE(DATEVALUE(C8&"-01"),3))>0,1,0) -> 0 | J8: =IF(COUNTIFS('📋 Транзакції'!$B$5:$B$3623,A8,'📋 Транзакції'!$C$5:$C$3623,">="&EDATE(DATEVALUE(C8&"-01"),3),'📋 Транзакції'!$C$5:$C$3623,"<"&EDATE(DATEVALUE(C8&"-01"),4))>0,1,0) -> 0 | K8: =IF(COUNTIFS('📋 Транзакції'!$B$5:$B$3623,A8,'📋 Транзакції'!$C$5:$C$3623,">="&EDATE(DATEVALUE(C8&"-01"),4),'📋 Транзакції'!$C$5:$C$3623,"<"&EDATE(DATEVALUE(C8&"-01"),5))>0,1,0) -> 0 | L8: =IF(COUNTIFS('📋 Транзакції'!$B$5:$B$3623,A8,'📋 Транзакції'!$C$5:$C$3623,">="&EDATE(DATEVALUE(C8&"-01"),5),'📋 Транзакції'!$C$5:$C$3623,"<"&EDATE(DATEVALUE(C8&"-01"),6))>0,1,0) -> 0 | M8: =IF(COUNTIFS('📋 Транзакції'!$B$5:$B$3623,A8,'📋 Транзакції'!$C$5:$C$3623,">="&EDATE(DATEVALUE(C8&"-01"),6),'📋 Транзакції'!$C$5:$C$3623,"<"&EDATE(DATEVALUE(C8&"-01"),7))>0,1,0) -> 0 | N8: =IF(COUNTIFS('📋 Транзакції'!$B$5:$B$3623,A8,'📋 Транзакції'!$C$5:$C$3623,">="&EDATE(DATEVALUE(C8&"-01"),7),'📋 Транзакції'!$C$5:$C$3623,"<"&EDATE(DATEVALUE(C8&"-01"),8))>0,1,0) -> 0 | O8: =IF(COUNTIFS('📋 Транзакції'!$B$5:$B$3623,A8,'📋 Транзакції'!$C$5:$C$3623,">="&EDATE(DATEVALUE(C8&"-01"),8),'📋 Транзакції'!$C$5:$C$3623,"<"&EDATE(DATEVALUE(C8&"-01"),9))>0,1,0) -> 0 | P8: =IF(COUNTIFS('📋 Транзакції'!$B$5:$B$3623,A8,'📋 Транзакції'!$C$5:$C$3623,">="&EDATE(DATEVALUE(C8&"-01"),9),'📋 Транзакції'!$C$5:$C$3623,"<"&EDATE(DATEVALUE(C8&"-01"),10))>0,1,0) -> 0 | Q8: =IF(COUNTIFS('📋 Транзакції'!$B$5:$B$3623,A8,'📋 Транзакції'!$C$5:$C$3623,">="&EDATE(DATEVALUE(C8&"-01"),10),'📋 Транзакції'!$C$5:$C$3623,"<"&EDATE(DATEVALUE(C8&"-01"),11))>0,1,0) -> 0 | R8: =IF(COUNTIFS('📋 Транзакції'!$B$5:$B$3623,A8,'📋 Транзакції'!$C$5:$C$3623,">="&EDATE(DATEVALUE(C8&"-01"),11),'📋 Транзакції'!$C$5:$C$3623,"<"&EDATE(DATEVALUE(C8&"-01"),12))>0,1,0) -> 0 | S8: =SUMIFS('📋 Транзакції'!$F$5:$F$3623,'📋 Транзакції'!$B$5:$B$3623,A8,'📋 Транзакції'!$C$5:$C$3623,">="&EDATE(DATEVALUE(C8&"-01"),0),'📋 Транзакції'!$C$5:$C$3623,"<"&EDATE(DATEVALUE(C8&"-01"),1)) -> 19.99 | T8: =SUMIFS('📋 Транзакції'!$F$5:$F$3623,'📋 Транзакції'!$B$5:$B$3623,A8,'📋 Транзакції'!$C$5:$C$3623,">="&EDATE(DATEVALUE(C8&"-01"),1),'📋 Транзакції'!$C$5:$C$3623,"<"&EDATE(DATEVALUE(C8&"-01"),2)) -> 19.99 | U8: =SUMIFS('📋 Транзакції'!$F$5:$F$3623,'📋 Транзакції'!$B$5:$B$3623,A8,'📋 Транзакції'!$C$5:$C$3623,">="&EDATE(DATEVALUE(C8&"-01"),2),'📋 Транзакції'!$C$5:$C$3623,"<"&EDATE(DATEVALUE(C8&"-01"),3)) -> 0 | V8: =SUMIFS('📋 Транзакції'!$F$5:$F$3623,'📋 Транзакції'!$B$5:$B$3623,A8,'📋 Транзакції'!$C$5:$C$3623,">="&EDATE(DATEVALUE(C8&"-01"),3),'📋 Транзакції'!$C$5:$C$3623,"<"&EDATE(DATEVALUE(C8&"-01"),4)) -> 0 | W8: =SUMIFS('📋 Транзакції'!$F$5:$F$3623,'📋 Транзакції'!$B$5:$B$3623,A8,'📋 Транзакції'!$C$5:$C$3623,">="&EDATE(DATEVALUE(C8&"-01"),4),'📋 Транзакції'!$C$5:$C$3623,"<"&EDATE(DATEVALUE(C8&"-01"),5)) -> 0 | X8: =SUMIFS('📋 Транзакції'!$F$5:$F$3623,'📋 Транзакції'!$B$5:$B$3623,A8,'📋 Транзакції'!$C$5:$C$3623,">="&EDATE(DATEVALUE(C8&"-01"),5),'📋 Транзакції'!$C$5:$C$3623,"<"&EDATE(DATEVALUE(C8&"-01"),6)) -> 0 | Y8: =SUMIFS('📋 Транзакції'!$F$5:$F$3623,'📋 Транзакції'!$B$5:$B$3623,A8,'📋 Транзакції'!$C$5:$C$3623,">="&EDATE(DATEVALUE(C8&"-01"),6),'📋 Транзакції'!$C$5:$C$3623,"<"&EDATE(DATEVALUE(C8&"-01"),7)) -> 0 | Z8: =SUMIFS('📋 Транзакції'!$F$5:$F$3623,'📋 Транзакції'!$B$5:$B$3623,A8,'📋 Транзакції'!$C$5:$C$3623,">="&EDATE(DATEVALUE(C8&"-01"),7),'📋 Транзакції'!$C$5:$C$3623,"<"&EDATE(DATEVALUE(C8&"-01"),8)) -> 0 | AA8: =SUMIFS('📋 Транзакції'!$F$5:$F$3623,'📋 Транзакції'!$B$5:$B$3623,A8,'📋 Транзакції'!$C$5:$C$3623,">="&EDATE(DATEVALUE(C8&"-01"),8),'📋 Транзакції'!$C$5:$C$3623,"<"&EDATE(DATEVALUE(C8&"-01"),9)) -> 0 | AB8: =SUMIFS('📋 Транзакції'!$F$5:$F$3623,'📋 Транзакції'!$B$5:$B$3623,A8,'📋 Транзакції'!$C$5:$C$3623,">="&EDATE(DATEVALUE(C8&"-01"),9),'📋 Транзакції'!$C$5:$C$3623,"<"&EDATE(DATEVALUE(C8&"-01"),10)) -> 0 | AC8: =SUMIFS('📋 Транзакції'!$F$5:$F$3623,'📋 Транзакції'!$B$5:$B$3623,A8,'📋 Транзакції'!$C$5:$C$3623,">="&EDATE(DATEVALUE(C8&"-01"),10),'📋 Транзакції'!$C$5:$C$3623,"<"&EDATE(DATEVALUE(C8&"-01"),11)) -> 0 | AD8: =SUMIFS('📋 Транзакції'!$F$5:$F$3623,'📋 Транзакції'!$B$5:$B$3623,A8,'📋 Транзакції'!$C$5:$C$3623,">="&EDATE(DATEVALUE(C8&"-01"),11),'📋 Транзакції'!$C$5:$C$3623,"<"&EDATE(DATEVALUE(C8&"-01"),12)) -> 0
A9: ='📋 Реєстрації'!A9:A610 -> U0291 | B9: {=INDEX('📋 Транзакції'!$C$5:$C$3623,MATCH(A9,'📋 Транзакції'!$B$5:$B$3623,0))} -> 45294 | C9: =TEXT(B9,"YYYY-MM") -> 2024-01 | D9: =COUNTIF('📋 Транзакції'!$B$5:$B$3623,A9) -> 3 | E9: =SUMIF('📋 Транзакції'!$B$5:$B$3623,A9,'📋 Транзакції'!$F$5:$F$3623) -> 39.98 | F9: =INT($A$1-MAXIFS('📋 Транзакції'!$C$5:$C$3623,'📋 Транзакції'!$B$5:$B$3623,A9)) -> 416 | G9: =IF(COUNTIFS('📋 Транзакції'!$B$5:$B$3623,A9,'📋 Транзакції'!$C$5:$C$3623,">="&EDATE(DATEVALUE(C9&"-01"),0),'📋 Транзакції'!$C$5:$C$3623,"<"&EDATE(DATEVALUE(C9&"-01"),1))>0,1,0) -> 1 | H9: =IF(COUNTIFS('📋 Транзакції'!$B$5:$B$3623,A9,'📋 Транзакції'!$C$5:$C$3623,">="&EDATE(DATEVALUE(C9&"-01"),1),'📋 Транзакції'!$C$5:$C$3623,"<"&EDATE(DATEVALUE(C9&"-01"),2))>0,1,0) -> 1 | I9: =IF(COUNTIFS('📋 Транзакції'!$B$5:$B$3623,A9,'📋 Транзакції'!$C$5:$C$3623,">="&EDATE(DATEVALUE(C9&"-01"),2),'📋 Транзакції'!$C$5:$C$3623,"<"&EDATE(DATEVALUE(C9&"-01"),3))>0,1,0) -> 0 | J9: =IF(COUNTIFS('📋 Транзакції'!$B$5:$B$3623,A9,'📋 Транзакції'!$C$5:$C$3623,">="&EDATE(DATEVALUE(C9&"-01"),3),'📋 Транзакції'!$C$5:$C$3623,"<"&EDATE(DATEVALUE(C9&"-01"),4))>0,1,0) -> 0 | K9: =IF(COUNTIFS('📋 Транзакції'!$B$5:$B$3623,A9,'📋 Транзакції'!$C$5:$C$3623,">="&EDATE(DATEVALUE(C9&"-01"),4),'📋 Транзакції'!$C$5:$C$3623,"<"&EDATE(DATEVALUE(C9&"-01"),5))>0,1,0) -> 0 | L9: =IF(COUNTIFS('📋 Транзакції'!$B$5:$B$3623,A9,'📋 Транзакції'!$C$5:$C$3623,">="&EDATE(DATEVALUE(C9&"-01"),5),'📋 Транзакції'!$C$5:$C$3623,"<"&EDATE(DATEVALUE(C9&"-01"),6))>0,1,0) -> 0 | M9: =IF(COUNTIFS('📋 Транзакції'!$B$5:$B$3623,A9,'📋 Транзакції'!$C$5:$C$3623,">="&EDATE(DATEVALUE(C9&"-01"),6),'📋 Транзакції'!$C$5:$C$3623,"<"&EDATE(DATEVALUE(C9&"-01"),7))>0,1,0) -> 0 | N9: =IF(COUNTIFS('📋 Транзакції'!$B$5:$B$3623,A9,'📋 Транзакції'!$C$5:$C$3623,">="&EDATE(DATEVALUE(C9&"-01"),7),'📋 Транзакції'!$C$5:$C$3623,"<"&EDATE(DATEVALUE(C9&"-01"),8))>0,1,0) -> 0 | O9: =IF(COUNTIFS('📋 Транзакції'!$B$5:$B$3623,A9,'📋 Транзакції'!$C$5:$C$3623,">="&EDATE(DATEVALUE(C9&"-01"),8),'📋 Транзакції'!$C$5:$C$3623,"<"&EDATE(DATEVALUE(C9&"-01"),9))>0,1,0) -> 0 | P9: =IF(COUNTIFS('📋 Транзакції'!$B$5:$B$3623,A9,'📋 Транзакції'!$C$5:$C$3623,">="&EDATE(DATEVALUE(C9&"-01"),9),'📋 Транзакції'!$C$5:$C$3623,"<"&EDATE(DATEVALUE(C9&"-01"),10))>0,1,0) -> 0 | Q9: =IF(COUNTIFS('📋 Транзакції'!$B$5:$B$3623,A9,'📋 Транзакції'!$C$5:$C$3623,">="&EDATE(DATEVALUE(C9&"-01"),10),'📋 Транзакції'!$C$5:$C$3623,"<"&EDATE(DATEVALUE(C9&"-01"),11))>0,1,0) -> 0 | R9: =IF(COUNTIFS('📋 Транзакції'!$B$5:$B$3623,A9,'📋 Транзакції'!$C$5:$C$3623,">="&EDATE(DATEVALUE(C9&"-01"),11),'📋 Транзакції'!$C$5:$C$3623,"<"&EDATE(DATEVALUE(C9&"-01"),12))>0,1,0) -> 0 | S9: =SUMIFS('📋 Транзакції'!$F$5:$F$3623,'📋 Транзакції'!$B$5:$B$3623,A9,'📋 Транзакції'!$C$5:$C$3623,">="&EDATE(DATEVALUE(C9&"-01"),0),'📋 Транзакції'!$C$5:$C$3623,"<"&EDATE(DATEVALUE(C9&"-01"),1)) -> 19.99 | T9: =SUMIFS('📋 Транзакції'!$F$5:$F$3623,'📋 Транзакції'!$B$5:$B$3623,A9,'📋 Транзакції'!$C$5:$C$3623,">="&EDATE(DATEVALUE(C9&"-01"),1),'📋 Транзакції'!$C$5:$C$3623,"<"&EDATE(DATEVALUE(C9&"-01"),2)) -> 19.99 | U9: =SUMIFS('📋 Транзакції'!$F$5:$F$3623,'📋 Транзакції'!$B$5:$B$3623,A9,'📋 Транзакції'!$C$5:$C$3623,">="&EDATE(DATEVALUE(C9&"-01"),2),'📋 Транзакції'!$C$5:$C$3623,"<"&EDATE(DATEVALUE(C9&"-01"),3)) -> 0 | V9: =SUMIFS('📋 Транзакції'!$F$5:$F$3623,'📋 Транзакції'!$B$5:$B$3623,A9,'📋 Транзакції'!$C$5:$C$3623,">="&EDATE(DATEVALUE(C9&"-01"),3),'📋 Транзакції'!$C$5:$C$3623,"<"&EDATE(DATEVALUE(C9&"-01"),4)) -> 0 | W9: =SUMIFS('📋 Транзакції'!$F$5:$F$3623,'📋 Транзакції'!$B$5:$B$3623,A9,'📋 Транзакції'!$C$5:$C$3623,">="&EDATE(DATEVALUE(C9&"-01"),4),'📋 Транзакції'!$C$5:$C$3623,"<"&EDATE(DATEVALUE(C9&"-01"),5)) -> 0 | X9: =SUMIFS('📋 Транзакції'!$F$5:$F$3623,'📋 Транзакції'!$B$5:$B$3623,A9,'📋 Транзакції'!$C$5:$C$3623,">="&EDATE(DATEVALUE(C9&"-01"),5),'📋 Транзакції'!$C$5:$C$3623,"<"&EDATE(DATEVALUE(C9&"-01"),6)) -> 0 | Y9: =SUMIFS('📋 Транзакції'!$F$5:$F$3623,'📋 Транзакції'!$B$5:$B$3623,A9,'📋 Транзакції'!$C$5:$C$3623,">="&EDATE(DATEVALUE(C9&"-01"),6),'📋 Транзакції'!$C$5:$C$3623,"<"&EDATE(DATEVALUE(C9&"-01"),7)) -> 0 | Z9: =SUMIFS('📋 Транзакції'!$F$5:$F$3623,'📋 Транзакції'!$B$5:$B$3623,A9,'📋 Транзакції'!$C$5:$C$3623,">="&EDATE(DATEVALUE(C9&"-01"),7),'📋 Транзакції'!$C$5:$C$3623,"<"&EDATE(DATEVALUE(C9&"-01"),8)) -> 0 | AA9: =SUMIFS('📋 Транзакції'!$F$5:$F$3623,'📋 Транзакції'!$B$5:$B$3623,A9,'📋 Транзакції'!$C$5:$C$3623,">="&EDATE(DATEVALUE(C9&"-01"),8),'📋 Транзакції'!$C$5:$C$3623,"<"&EDATE(DATEVALUE(C9&"-01"),9)) -> 0 | AB9: =SUMIFS('📋 Транзакції'!$F$5:$F$3623,'📋 Транзакції'!$B$5:$B$3623,A9,'📋 Транзакції'!$C$5:$C$3623,">="&EDATE(DATEVALUE(C9&"-01"),9),'📋 Транзакції'!$C$5:$C$3623,"<"&EDATE(DATEVALUE(C9&"-01"),10)) -> 0 | AC9: =SUMIFS('📋 Транзакції'!$F$5:$F$3623,'📋 Транзакції'!$B$5:$B$3623,A9,'📋 Транзакції'!$C$5:$C$3623,">="&EDATE(DATEVALUE(C9&"-01"),10),'📋 Транзакції'!$C$5:$C$3623,"<"&EDATE(DATEVALUE(C9&"-01"),11)) -> 0 | AD9: =SUMIFS('📋 Транзакції'!$F$5:$F$3623,'📋 Транзакції'!$B$5:$B$3623,A9,'📋 Транзакції'!$C$5:$C$3623,">="&EDATE(DATEVALUE(C9&"-01"),11),'📋 Транзакції'!$C$5:$C$3623,"<"&EDATE(DATEVALUE(C9&"-01"),12)) -> 0
A10: ='📋 Реєстрації'!A10:A611 -> U0408 | B10: {=INDEX('📋 Транзакції'!$C$5:$C$3623,MATCH(A10,'📋 Транзакції'!$B$5:$B$3623,0))} -> 45294 | C10: =TEXT(B10,"YYYY-MM") -> 2024-01 | D10: =COUNTIF('📋 Транзакції'!$B$5:$B$3623,A10) -> 3 | E10: =SUMIF('📋 Транзакції'!$B$5:$B$3623,A10,'📋 Транзакції'!$F$5:$F$3623) -> 39.98 | F10: =INT($A$1-MAXIFS('📋 Транзакції'!$C$5:$C$3623,'📋 Транзакції'!$B$5:$B$3623,A10)) -> 416 | G10: =IF(COUNTIFS('📋 Транзакції'!$B$5:$B$3623,A10,'📋 Транзакції'!$C$5:$C$3623,">="&EDATE(DATEVALUE(C10&"-01"),0),'📋 Транзакції'!$C$5:$C$3623,"<"&EDATE(DATEVALUE(C10&"-01"),1))>0,1,0) -> 1 | H10: =IF(COUNTIFS('📋 Транзакції'!$B$5:$B$3623,A10,'📋 Транзакції'!$C$5:$C$3623,">="&EDATE(DATEVALUE(C10&"-01"),1),'📋 Транзакції'!$C$5:$C$3623,"<"&EDATE(DATEVALUE(C10&"-01"),2))>0,1,0) -> 1 | I10: =IF(COUNTIFS('📋 Транзакції'!$B$5:$B$3623,A10,'📋 Транзакції'!$C$5:$C$3623,">="&EDATE(DATEVALUE(C10&"-01"),2),'📋 Транзакції'!$C$5:$C$3623,"<"&EDATE(DATEVALUE(C10&"-01"),3))>0,1,0) -> 0 | J10: =IF(COUNTIFS('📋 Транзакції'!$B$5:$B$3623,A10,'📋 Транзакції'!$C$5:$C$3623,">="&EDATE(DATEVALUE(C10&"-01"),3),'📋 Транзакції'!$C$5:$C$3623,"<"&EDATE(DATEVALUE(C10&"-01"),4))>0,1,0) -> 0 | K10: =IF(COUNTIFS('📋 Транзакції'!$B$5:$B$3623,A10,'📋 Транзакції'!$C$5:$C$3623,">="&EDATE(DATEVALUE(C10&"-01"),4),'📋 Транзакції'!$C$5:$C$3623,"<"&EDATE(DATEVALUE(C10&"-01"),5))>0,1,0) -> 0 | L10: =IF(COUNTIFS('📋 Транзакції'!$B$5:$B$3623,A10,'📋 Транзакції'!$C$5:$C$3623,">="&EDATE(DATEVALUE(C10&"-01"),5),'📋 Транзакції'!$C$5:$C$3623,"<"&EDATE(DATEVALUE(C10&"-01"),6))>0,1,0) -> 0 | M10: =IF(COUNTIFS('📋 Транзакції'!$B$5:$B$3623,A10,'📋 Транзакції'!$C$5:$C$3623,">="&EDATE(DATEVALUE(C10&"-01"),6),'📋 Транзакції'!$C$5:$C$3623,"<"&EDATE(DATEVALUE(C10&"-01"),7))>0,1,0) -> 0 | N10: =IF(COUNTIFS('📋 Транзакції'!$B$5:$B$3623,A10,'📋 Транзакції'!$C$5:$C$3623,">="&EDATE(DATEVALUE(C10&"-01"),7),'📋 Транзакції'!$C$5:$C$3623,"<"&EDATE(DATEVALUE(C10&"-01"),8))>0,1,0) -> 0 | O10: =IF(COUNTIFS('📋 Транзакції'!$B$5:$B$3623,A10,'📋 Транзакції'!$C$5:$C$3623,">="&EDATE(DATEVALUE(C10&"-01"),8),'📋 Транзакції'!$C$5:$C$3623,"<"&EDATE(DATEVALUE(C10&"-01"),9))>0,1,0) -> 0 | P10: =IF(COUNTIFS('📋 Транзакції'!$B$5:$B$3623,A10,'📋 Транзакції'!$C$5:$C$3623,">="&EDATE(DATEVALUE(C10&"-01"),9),'📋 Транзакції'!$C$5:$C$3623,"<"&EDATE(DATEVALUE(C10&"-01"),10))>0,1,0) -> 0 | Q10: =IF(COUNTIFS('📋 Транзакції'!$B$5:$B$3623,A10,'📋 Транзакції'!$C$5:$C$3623,">="&EDATE(DATEVALUE(C10&"-01"),10),'📋 Транзакції'!$C$5:$C$3623,"<"&EDATE(DATEVALUE(C10&"-01"),11))>0,1,0) -> 0 | R10: =IF(COUNTIFS('📋 Транзакції'!$B$5:$B$3623,A10,'📋 Транзакції'!$C$5:$C$3623,">="&EDATE(DATEVALUE(C10&"-01"),11),'📋 Транзакції'!$C$5:$C$3623,"<"&EDATE(DATEVALUE(C10&"-01"),12))>0,1,0) -> 0 | S10: =SUMIFS('📋 Транзакції'!$F$5:$F$3623,'📋 Транзакції'!$B$5:$B$3623,A10,'📋 Транзакції'!$C$5:$C$3623,">="&EDATE(DATEVALUE(C10&"-01"),0),'📋 Транзакції'!$C$5:$C$3623,"<"&EDATE(DATEVALUE(C10&"-01"),1)) -> 19.99 | T10: =SUMIFS('📋 Транзакції'!$F$5:$F$3623,'📋 Транзакції'!$B$5:$B$3623,A10,'📋 Транзакції'!$C$5:$C$3623,">="&EDATE(DATEVALUE(C10&"-01"),1),'📋 Транзакції'!$C$5:$C$3623,"<"&EDATE(DATEVALUE(C10&"-01"),2)) -> 19.99 | U10: =SUMIFS('📋 Транзакції'!$F$5:$F$3623,'📋 Транзакції'!$B$5:$B$3623,A10,'📋 Транзакції'!$C$5:$C$3623,">="&EDATE(DATEVALUE(C10&"-01"),2),'📋 Транзакції'!$C$5:$C$3623,"<"&EDATE(DATEVALUE(C10&"-01"),3)) -> 0 | V10: =SUMIFS('📋 Транзакції'!$F$5:$F$3623,'📋 Транзакції'!$B$5:$B$3623,A10,'📋 Транзакції'!$C$5:$C$3623,">="&EDATE(DATEVALUE(C10&"-01"),3),'📋 Транзакції'!$C$5:$C$3623,"<"&EDATE(DATEVALUE(C10&"-01"),4)) -> 0 | W10: =SUMIFS('📋 Транзакції'!$F$5:$F$3623,'📋 Транзакції'!$B$5:$B$3623,A10,'📋 Транзакції'!$C$5:$C$3623,">="&EDATE(DATEVALUE(C10&"-01"),4),'📋 Транзакції'!$C$5:$C$3623,"<"&EDATE(DATEVALUE(C10&"-01"),5)) -> 0 | X10: =SUMIFS('📋 Транзакції'!$F$5:$F$3623,'📋 Транзакції'!$B$5:$B$3623,A10,'📋 Транзакції'!$C$5:$C$3623,">="&EDATE(DATEVALUE(C10&"-01"),5),'📋 Транзакції'!$C$5:$C$3623,"<"&EDATE(DATEVALUE(C10&"-01"),6)) -> 0 | Y10: =SUMIFS('📋 Транзакції'!$F$5:$F$3623,'📋 Транзакції'!$B$5:$B$3623,A10,'📋 Транзакції'!$C$5:$C$3623,">="&EDATE(DATEVALUE(C10&"-01"),6),'📋 Транзакції'!$C$5:$C$3623,"<"&EDATE(DATEVALUE(C10&"-01"),7)) -> 0 | Z10: =SUMIFS('📋 Транзакції'!$F$5:$F$3623,'📋 Транзакції'!$B$5:$B$3623,A10,'📋 Транзакції'!$C$5:$C$3623,">="&EDATE(DATEVALUE(C10&"-01"),7),'📋 Транзакції'!$C$5:$C$3623,"<"&EDATE(DATEVALUE(C10&"-01"),8)) -> 0 | AA10: =SUMIFS('📋 Транзакції'!$F$5:$F$3623,'📋 Транзакції'!$B$5:$B$3623,A10,'📋 Транзакції'!$C$5:$C$3623,">="&EDATE(DATEVALUE(C10&"-01"),8),'📋 Транзакції'!$C$5:$C$3623,"<"&EDATE(DATEVALUE(C10&"-01"),9)) -> 0 | AB10: =SUMIFS('📋 Транзакції'!$F$5:$F$3623,'📋 Транзакції'!$B$5:$B$3623,A10,'📋 Транзакції'!$C$5:$C$3623,">="&EDATE(DATEVALUE(C10&"-01"),9),'📋 Транзакції'!$C$5:$C$3623,"<"&EDATE(DATEVALUE(C10&"-01"),10)) -> 0 | AC10: =SUMIFS('📋 Транзакції'!$F$5:$F$3623,'📋 Транзакції'!$B$5:$B$3623,A10,'📋 Транзакції'!$C$5:$C$3623,">="&EDATE(DATEVALUE(C10&"-01"),10),'📋 Транзакції'!$C$5:$C$3623,"<"&EDATE(DATEVALUE(C10&"-01"),11)) -> 0 | AD10: =SUMIFS('📋 Транзакції'!$F$5:$F$3623,'📋 Транзакції'!$B$5:$B$3623,A10,'📋 Транзакції'!$C$5:$C$3623,">="&EDATE(DATEVALUE(C10&"-01"),11),'📋 Транзакції'!$C$5:$C$3623,"<"&EDATE(DATEVALUE(C10&"-01"),12)) -> 0
A11: ='📋 Реєстрації'!A11:A612 -> U0883 | B11: {=INDEX('📋 Транзакції'!$C$5:$C$3623,MATCH(A11,'📋 Транзакції'!$B$5:$B$3623,0))} -> 45294 | C11: =TEXT(B11,"YYYY-MM") -> 2024-01 | D11: =COUNTIF('📋 Транзакції'!$B$5:$B$3623,A11) -> 16 | E11: =SUMIF('📋 Транзакції'!$B$5:$B$3623,A11,'📋 Транзакції'!$F$5:$F$3623) -> 299.85 | F11: =INT($A$1-MAXIFS('📋 Транзакції'!$C$5:$C$3623,'📋 Транзакції'!$B$5:$B$3623,A11)) -> 26 | G11: =IF(COUNTIFS('📋 Транзакції'!$B$5:$B$3623,A11,'📋 Транзакції'!$C$5:$C$3623,">="&EDATE(DATEVALUE(C11&"-01"),0),'📋 Транзакції'!$C$5:$C$3623,"<"&EDATE(DATEVALUE(C11&"-01"),1))>0,1,0) -> 1 | H11: =IF(COUNTIFS('📋 Транзакції'!$B$5:$B$3623,A11,'📋 Транзакції'!$C$5:$C$3623,">="&EDATE(DATEVALUE(C11&"-01"),1),'📋 Транзакції'!$C$5:$C$3623,"<"&EDATE(DATEVALUE(C11&"-01"),2))>0,1,0) -> 1 | I11: =IF(COUNTIFS('📋 Транзакції'!$B$5:$B$3623,A11,'📋 Транзакції'!$C$5:$C$3623,">="&EDATE(DATEVALUE(C11&"-01"),2),'📋 Транзакції'!$C$5:$C$3623,"<"&EDATE(DATEVALUE(C11&"-01"),3))>0,1,0) -> 1 | J11: =IF(COUNTIFS('📋 Транзакції'!$B$5:$B$3623,A11,'📋 Транзакції'!$C$5:$C$3623,">="&EDATE(DATEVALUE(C11&"-01"),3),'📋 Транзакції'!$C$5:$C$3623,"<"&EDATE(DATEVALUE(C11&"-01"),4))>0,1,0) -> 1 | K11: =IF(COUNTIFS('📋 Транзакції'!$B$5:$B$3623,A11,'📋 Транзакції'!$C$5:$C$3623,">="&EDATE(DATEVALUE(C11&"-01"),4),'📋 Транзакції'!$C$5:$C$3623,"<"&EDATE(DATEVALUE(C11&"-01"),5))>0,1,0) -> 1 | L11: =IF(COUNTIFS('📋 Транзакції'!$B$5:$B$3623,A11,'📋 Транзакції'!$C$5:$C$3623,">="&EDATE(DATEVALUE(C11&"-01"),5),'📋 Транзакції'!$C$5:$C$3623,"<"&EDATE(DATEVALUE(C11&"-01"),6))>0,1,0) -> 1 | M11: =IF(COUNTIFS('📋 Транзакції'!$B$5:$B$3623,A11,'📋 Транзакції'!$C$5:$C$3623,">="&EDATE(DATEVALUE(C11&"-01"),6),'📋 Транзакції'!$C$5:$C$3623,"<"&EDATE(DATEVALUE(C11&"-01"),7))>0,1,0) -> 1 | N11: =IF(COUNTIFS('📋 Транзакції'!$B$5:$B$3623,A11,'📋 Транзакції'!$C$5:$C$3623,">="&EDATE(DATEVALUE(C11&"-01"),7),'📋 Транзакції'!$C$5:$C$3623,"<"&EDATE(DATEVALUE(C11&"-01"),8))>0,1,0) -> 1 | O11: =IF(COUNTIFS('📋 Транзакції'!$B$5:$B$3623,A11,'📋 Транзакції'!$C$5:$C$3623,">="&EDATE(DATEVALUE(C11&"-01"),8),'📋 Транзакції'!$C$5:$C$3623,"<"&EDATE(DATEVALUE(C11&"-01"),9))>0,1,0) -> 1 | P11: =IF(COUNTIFS('📋 Транзакції'!$B$5:$B$3623,A11,'📋 Транзакції'!$C$5:$C$3623,">="&EDATE(DATEVALUE(C11&"-01"),9),'📋 Транзакції'!$C$5:$C$3623,"<"&EDATE(DATEVALUE(C11&"-01"),10))>0,1,0) -> 1 | Q11: =IF(COUNTIFS('📋 Транзакції'!$B$5:$B$3623,A11,'📋 Транзакції'!$C$5:$C$3623,">="&EDATE(DATEVALUE(C11&"-01"),10),'📋 Транзакції'!$C$5:$C$3623,"<"&EDATE(DATEVALUE(C11&"-01"),11))>0,1,0) -> 1 | R11: =IF(COUNTIFS('📋 Транзакції'!$B$5:$B$3623,A11,'📋 Транзакції'!$C$5:$C$3623,">="&EDATE(DATEVALUE(C11&"-01"),11),'📋 Транзакції'!$C$5:$C$3623,"<"&EDATE(DATEVALUE(C11&"-01"),12))>0,1,0) -> 1 | S11: =SUMIFS('📋 Транзакції'!$F$5:$F$3623,'📋 Транзакції'!$B$5:$B$3623,A11,'📋 Транзакції'!$C$5:$C$3623,">="&EDATE(DATEVALUE(C11&"-01"),0),'📋 Транзакції'!$C$5:$C$3623,"<"&EDATE(DATEVALUE(C11&"-01"),1)) -> 19.99 | T11: =SUMIFS('📋 Транзакції'!$F$5:$F$3623,'📋 Транзакції'!$B$5:$B$3623,A11,'📋 Транзакції'!$C$5:$C$3623,">="&EDATE(DATEVALUE(C11&"-01"),1),'📋 Транзакції'!$C$5:$C$3623,"<"&EDATE(DATEVALUE(C11&"-01"),2)) -> 19.99 | U11: =SUMIFS('📋 Транзакції'!$F$5:$F$3623,'📋 Транзакції'!$B$5:$B$3623,A11,'📋 Транзакції'!$C$5:$C$3623,">="&EDATE(DATEVALUE(C11&"-01"),2),'📋 Транзакції'!$C$5:$C$3623,"<"&EDATE(DATEVALUE(C11&"-01"),3)) -> 19.99 | V11: =SUMIFS('📋 Транзакції'!$F$5:$F$3623,'📋 Транзакції'!$B$5:$B$3623,A11,'📋 Транзакції'!$C$5:$C$3623,">="&EDATE(DATEVALUE(C11&"-01"),3),'📋 Транзакції'!$C$5:$C$3623,"<"&EDATE(DATEVALUE(C11&"-01"),4)) -> 19.99 | W11: =SUMIFS('📋 Транзакції'!$F$5:$F$3623,'📋 Транзакції'!$B$5:$B$3623,A11,'📋 Транзакції'!$C$5:$C$3623,">="&EDATE(DATEVALUE(C11&"-01"),4),'📋 Транзакції'!$C$5:$C$3623,"<"&EDATE(DATEVALUE(C11&"-01"),5)) -> 19.99 | X11: =SUMIFS('📋 Транзакції'!$F$5:$F$3623,'📋 Транзакції'!$B$5:$B$3623,A11,'📋 Транзакції'!$C$5:$C$3623,">="&EDATE(DATEVALUE(C11&"-01"),5),'📋 Транзакції'!$C$5:$C$3623,"<"&EDATE(DATEVALUE(C11&"-01"),6)) -> 19.99 | Y11: =SUMIFS('📋 Транзакції'!$F$5:$F$3623,'📋 Транзакції'!$B$5:$B$3623,A11,'📋 Транзакції'!$C$5:$C$3623,">="&EDATE(DATEVALUE(C11&"-01"),6),'📋 Транзакції'!$C$5:$C$3623,"<"&EDATE(DATEVALUE(C11&"-01"),7)) -> 19.99 | Z11: =SUMIFS('📋 Транзакції'!$F$5:$F$3623,'📋 Транзакції'!$B$5:$B$3623,A11,'📋 Транзакції'!$C$5:$C$3623,">="&EDATE(DATEVALUE(C11&"-01"),7),'📋 Транзакції'!$C$5:$C$3623,"<"&EDATE(DATEVALUE(C11&"-01"),8)) -> 19.99 | AA11: =SUMIFS('📋 Транзакції'!$F$5:$F$3623,'📋 Транзакції'!$B$5:$B$3623,A11,'📋 Транзакції'!$C$5:$C$3623,">="&EDATE(DATEVALUE(C11&"-01"),8),'📋 Транзакції'!$C$5:$C$3623,"<"&EDATE(DATEVALUE(C11&"-01"),9)) -> 19.99 | AB11: =SUMIFS('📋 Транзакції'!$F$5:$F$3623,'📋 Транзакції'!$B$5:$B$3623,A11,'📋 Транзакції'!$C$5:$C$3623,">="&EDATE(DATEVALUE(C11&"-01"),9),'📋 Транзакції'!$C$5:$C$3623,"<"&EDATE(DATEVALUE(C11&"-01"),10)) -> 19.99 | AC11: =SUMIFS('📋 Транзакції'!$F$5:$F$3623,'📋 Транзакції'!$B$5:$B$3623,A11,'📋 Транзакції'!$C$5:$C$3623,">="&EDATE(DATEVALUE(C11&"-01"),10),'📋 Транзакції'!$C$5:$C$3623,"<"&EDATE(DATEVALUE(C11&"-01"),11)) -> 19.99 | AD11: =SUMIFS('📋 Транзакції'!$F$5:$F$3623,'📋 Транзакції'!$B$5:$B$3623,A11,'📋 Транзакції'!$C$5:$C$3623,">="&EDATE(DATEVALUE(C11&"-01"),11),'📋 Транзакції'!$C$5:$C$3623,"<"&EDATE(DATEVALUE(C11&"-01"),12)) -> 19.99
A12: ='📋 Реєстрації'!A12:A613 -> U0333 | B12: {=INDEX('📋 Транзакції'!$C$5:$C$3623,MATCH(A12,'📋 Транзакції'!$B$5:$B$3623,0))} -> 45295 | C12: =TEXT(B12,"YYYY-MM") -> 2024-01 | D12: =COUNTIF('📋 Транзакції'!$B$5:$B$3623,A12) -> 16 | E12: =SUMIF('📋 Транзакції'!$B$5:$B$3623,A12,'📋 Транзакції'!$F$5:$F$3623) -> 299.85 | F12: =INT($A$1-MAXIFS('📋 Транзакції'!$C$5:$C$3623,'📋 Транзакції'!$B$5:$B$3623,A12)) -> 25 | G12: =IF(COUNTIFS('📋 Транзакції'!$B$5:$B$3623,A12,'📋 Транзакції'!$C$5:$C$3623,">="&EDATE(DATEVALUE(C12&"-01"),0),'📋 Транзакції'!$C$5:$C$3623,"<"&EDATE(DATEVALUE(C12&"-01"),1))>0,1,0) -> 1 | H12: =IF(COUNTIFS('📋 Транзакції'!$B$5:$B$3623,A12,'📋 Транзакції'!$C$5:$C$3623,">="&EDATE(DATEVALUE(C12&"-01"),1),'📋 Транзакції'!$C$5:$C$3623,"<"&EDATE(DATEVALUE(C12&"-01"),2))>0,1,0) -> 1 | I12: =IF(COUNTIFS('📋 Транзакції'!$B$5:$B$3623,A12,'📋 Транзакції'!$C$5:$C$3623,">="&EDATE(DATEVALUE(C12&"-01"),2),'📋 Транзакції'!$C$5:$C$3623,"<"&EDATE(DATEVALUE(C12&"-01"),3))>0,1,0) -> 1 | J12: =IF(COUNTIFS('📋 Транзакції'!$B$5:$B$3623,A12,'📋 Транзакції'!$C$5:$C$3623,">="&EDATE(DATEVALUE(C12&"-01"),3),'📋 Транзакції'!$C$5:$C$3623,"<"&EDATE(DATEVALUE(C12&"-01"),4))>0,1,0) -> 1 | K12: =IF(COUNTIFS('📋 Транзакції'!$B$5:$B$3623,A12,'📋 Транзакції'!$C$5:$C$3623,">="&EDATE(DATEVALUE(C12&"-01"),4),'📋 Транзакції'!$C$5:$C$3623,"<"&EDATE(DATEVALUE(C12&"-01"),5))>0,1,0) -> 1 | L12: =IF(COUNTIFS('📋 Транзакції'!$B$5:$B$3623,A12,'📋 Транзакції'!$C$5:$C$3623,">="&EDATE(DATEVALUE(C12&"-01"),5),'📋 Транзакції'!$C$5:$C$3623,"<"&EDATE(DATEVALUE(C12&"-01"),6))>0,1,0) -> 1 | M12: =IF(COUNTIFS('📋 Транзакції'!$B$5:$B$3623,A12,'📋 Транзакції'!$C$5:$C$3623,">="&EDATE(DATEVALUE(C12&"-01"),6),'📋 Транзакції'!$C$5:$C$3623,"<"&EDATE(DATEVALUE(C12&"-01"),7))>0,1,0) -> 1 | N12: =IF(COUNTIFS('📋 Транзакції'!$B$5:$B$3623,A12,'📋 Транзакції'!$C$5:$C$3623,">="&EDATE(DATEVALUE(C12&"-01"),7),'📋 Транзакції'!$C$5:$C$3623,"<"&EDATE(DATEVALUE(C12&"-01"),8))>0,1,0) -> 1 | O12: =IF(COUNTIFS('📋 Транзакції'!$B$5:$B$3623,A12,'📋 Транзакції'!$C$5:$C$3623,">="&EDATE(DATEVALUE(C12&"-01"),8),'📋 Транзакції'!$C$5:$C$3623,"<"&EDATE(DATEVALUE(C12&"-01"),9))>0,1,0) -> 1 | P12: =IF(COUNTIFS('📋 Транзакції'!$B$5:$B$3623,A12,'📋 Транзакції'!$C$5:$C$3623,">="&EDATE(DATEVALUE(C12&"-01"),9),'📋 Транзакції'!$C$5:$C$3623,"<"&EDATE(DATEVALUE(C12&"-01"),10))>0,1,0) -> 1 | Q12: =IF(COUNTIFS('📋 Транзакції'!$B$5:$B$3623,A12,'📋 Транзакції'!$C$5:$C$3623,">="&EDATE(DATEVALUE(C12&"-01"),10),'📋 Транзакції'!$C$5:$C$3623,"<"&EDATE(DATEVALUE(C12&"-01"),11))>0,1,0) -> 1 | R12: =IF(COUNTIFS('📋 Транзакції'!$B$5:$B$3623,A12,'📋 Транзакції'!$C$5:$C$3623,">="&EDATE(DATEVALUE(C12&"-01"),11),'📋 Транзакції'!$C$5:$C$3623,"<"&EDATE(DATEVALUE(C12&"-01"),12))>0,1,0) -> 1 | S12: =SUMIFS('📋 Транзакції'!$F$5:$F$3623,'📋 Транзакції'!$B$5:$B$3623,A12,'📋 Транзакції'!$C$5:$C$3623,">="&EDATE(DATEVALUE(C12&"-01"),0),'📋 Транзакції'!$C$5:$C$3623,"<"&EDATE(DATEVALUE(C12&"-01"),1)) -> 19.99 | T12: =SUMIFS('📋 Транзакції'!$F$5:$F$3623,'📋 Транзакції'!$B$5:$B$3623,A12,'📋 Транзакції'!$C$5:$C$3623,">="&EDATE(DATEVALUE(C12&"-01"),1),'📋 Транзакції'!$C$5:$C$3623,"<"&EDATE(DATEVALUE(C12&"-01"),2)) -> 19.99 | U12: =SUMIFS('📋 Транзакції'!$F$5:$F$3623,'📋 Транзакції'!$B$5:$B$3623,A12,'📋 Транзакції'!$C$5:$C$3623,">="&EDATE(DATEVALUE(C12&"-01"),2),'📋 Транзакції'!$C$5:$C$3623,"<"&EDATE(DATEVALUE(C12&"-01"),3)) -> 19.99 | V12: =SUMIFS('📋 Транзакції'!$F$5:$F$3623,'📋 Транзакції'!$B$5:$B$3623,A12,'📋 Транзакції'!$C$5:$C$3623,">="&EDATE(DATEVALUE(C12&"-01"),3),'📋 Транзакції'!$C$5:$C$3623,"<"&EDATE(DATEVALUE(C12&"-01"),4)) -> 19.99 | W12: =SUMIFS('📋 Транзакції'!$F$5:$F$3623,'📋 Транзакції'!$B$5:$B$3623,A12,'📋 Транзакції'!$C$5:$C$3623,">="&EDATE(DATEVALUE(C12&"-01"),4),'📋 Транзакції'!$C$5:$C$3623,"<"&EDATE(DATEVALUE(C12&"-01"),5)) -> 19.99 | X12: =SUMIFS('📋 Транзакції'!$F$5:$F$3623,'📋 Транзакції'!$B$5:$B$3623,A12,'📋 Транзакції'!$C$5:$C$3623,">="&EDATE(DATEVALUE(C12&"-01"),5),'📋 Транзакції'!$C$5:$C$3623,"<"&EDATE(DATEVALUE(C12&"-01"),6)) -> 19.99 | Y12: =SUMIFS('📋 Транзакції'!$F$5:$F$3623,'📋 Транзакції'!$B$5:$B$3623,A12,'📋 Транзакції'!$C$5:$C$3623,">="&EDATE(DATEVALUE(C12&"-01"),6),'📋 Транзакції'!$C$5:$C$3623,"<"&EDATE(DATEVALUE(C12&"-01"),7)) -> 19.99 | Z12: =SUMIFS('📋 Транзакції'!$F$5:$F$3623,'📋 Транзакції'!$B$5:$B$3623,A12,'📋 Транзакції'!$C$5:$C$3623,">="&EDATE(DATEVALUE(C12&"-01"),7),'📋 Транзакції'!$C$5:$C$3623,"<"&EDATE(DATEVALUE(C12&"-01"),8)) -> 19.99 | AA12: =SUMIFS('📋 Транзакції'!$F$5:$F$3623,'📋 Транзакції'!$B$5:$B$3623,A12,'📋 Транзакції'!$C$5:$C$3623,">="&EDATE(DATEVALUE(C12&"-01"),8),'📋 Транзакції'!$C$5:$C$3623,"<"&EDATE(DATEVALUE(C12&"-01"),9)) -> 19.99 | AB12: =SUMIFS('📋 Транзакції'!$F$5:$F$3623,'📋 Транзакції'!$B$5:$B$3623,A12,'📋 Транзакції'!$C$5:$C$3623,">="&EDATE(DATEVALUE(C12&"-01"),9),'📋 Транзакції'!$C$5:$C$3623,"<"&EDATE(DATEVALUE(C12&"-01"),10)) -> 19.99 | AC12: =SUMIFS('📋 Транзакції'!$F$5:$F$3623,'📋 Транзакції'!$B$5:$B$3623,A12,'📋 Транзакції'!$C$5:$C$3623,">="&EDATE(DATEVALUE(C12&"-01"),10),'📋 Транзакції'!$C$5:$C$3623,"<"&EDATE(DATEVALUE(C12&"-01"),11)) -> 19.99 | AD12: =SUMIFS('📋 Транзакції'!$F$5:$F$3623,'📋 Транзакції'!$B$5:$B$3623,A12,'📋 Транзакції'!$C$5:$C$3623,">="&EDATE(DATEVALUE(C12&"-01"),11),'📋 Транзакції'!$C$5:$C$3623,"<"&EDATE(DATEVALUE(C12&"-01"),12)) -> 19.99
A13: ='📋 Реєстрації'!A13:A614 -> U0172 | B13: {=INDEX('📋 Транзакції'!$C$5:$C$3623,MATCH(A13,'📋 Транзакції'!$B$5:$B$3623,0))} -> 45300 | C13: =TEXT(B13,"YYYY-MM") -> 2024-01 | D13: =COUNTIF('📋 Транзакції'!$B$5:$B$3623,A13) -> 10 | E13: =SUMIF('📋 Транзакції'!$B$5:$B$3623,A13,'📋 Транзакції'!$F$5:$F$3623) -> 179.91 | F13: =INT($A$1-MAXIFS('📋 Транзакції'!$C$5:$C$3623,'📋 Транзакції'!$B$5:$B$3623,A13)) -> 200 | G13: =IF(COUNTIFS('📋 Транзакції'!$B$5:$B$3623,A13,'📋 Транзакції'!$C$5:$C$3623,">="&EDATE(DATEVALUE(C13&"-01"),0),'📋 Транзакції'!$C$5:$C$3623,"<"&EDATE(DATEVALUE(C13&"-01"),1))>0,1,0) -> 1 | H13: =IF(COUNTIFS('📋 Транзакції'!$B$5:$B$3623,A13,'📋 Транзакції'!$C$5:$C$3623,">="&EDATE(DATEVALUE(C13&"-01"),1),'📋 Транзакції'!$C$5:$C$3623,"<"&EDATE(DATEVALUE(C13&"-01"),2))>0,1,0) -> 1 | I13: =IF(COUNTIFS('📋 Транзакції'!$B$5:$B$3623,A13,'📋 Транзакції'!$C$5:$C$3623,">="&EDATE(DATEVALUE(C13&"-01"),2),'📋 Транзакції'!$C$5:$C$3623,"<"&EDATE(DATEVALUE(C13&"-01"),3))>0,1,0) -> 1 | J13: =IF(COUNTIFS('📋 Транзакції'!$B$5:$B$3623,A13,'📋 Транзакції'!$C$5:$C$3623,">="&EDATE(DATEVALUE(C13&"-01"),3),'📋 Транзакції'!$C$5:$C$3623,"<"&EDATE(DATEVALUE(C13&"-01"),4))>0,1,0) -> 1 | K13: =IF(COUNTIFS('📋 Транзакції'!$B$5:$B$3623,A13,'📋 Транзакції'!$C$5:$C$3623,">="&EDATE(DATEVALUE(C13&"-01"),4),'📋 Транзакції'!$C$5:$C$3623,"<"&EDATE(DATEVALUE(C13&"-01"),5))>0,1,0) -> 1 | L13: =IF(COUNTIFS('📋 Транзакції'!$B$5:$B$3623,A13,'📋 Транзакції'!$C$5:$C$3623,">="&EDATE(DATEVALUE(C13&"-01"),5),'📋 Транзакції'!$C$5:$C$3623,"<"&EDATE(DATEVALUE(C13&"-01"),6))>0,1,0) -> 1 | M13: =IF(COUNTIFS('📋 Транзакції'!$B$5:$B$3623,A13,'📋 Транзакції'!$C$5:$C$3623,">="&EDATE(DATEVALUE(C13&"-01"),6),'📋 Транзакції'!$C$5:$C$3623,"<"&EDATE(DATEVALUE(C13&"-01"),7))>0,1,0) -> 1 | N13: =IF(COUNTIFS('📋 Транзакції'!$B$5:$B$3623,A13,'📋 Транзакції'!$C$5:$C$3623,">="&EDATE(DATEVALUE(C13&"-01"),7),'📋 Транзакції'!$C$5:$C$3623,"<"&EDATE(DATEVALUE(C13&"-01"),8))>0,1,0) -> 1 | O13: =IF(COUNTIFS('📋 Транзакції'!$B$5:$B$3623,A13,'📋 Транзакції'!$C$5:$C$3623,">="&EDATE(DATEVALUE(C13&"-01"),8),'📋 Транзакції'!$C$5:$C$3623,"<"&EDATE(DATEVALUE(C13&"-01"),9))>0,1,0) -> 1 | P13: =IF(COUNTIFS('📋 Транзакції'!$B$5:$B$3623,A13,'📋 Транзакції'!$C$5:$C$3623,">="&EDATE(DATEVALUE(C13&"-01"),9),'📋 Транзакції'!$C$5:$C$3623,"<"&EDATE(DATEVALUE(C13&"-01"),10))>0,1,0) -> 0 | Q13: =IF(COUNTIFS('📋 Транзакції'!$B$5:$B$3623,A13,'📋 Транзакції'!$C$5:$C$3623,">="&EDATE(DATEVALUE(C13&"-01"),10),'📋 Транзакції'!$C$5:$C$3623,"<"&EDATE(DATEVALUE(C13&"-01"),11))>0,1,0) -> 0 | R13: =IF(COUNTIFS('📋 Транзакції'!$B$5:$B$3623,A13,'📋 Транзакції'!$C$5:$C$3623,">="&EDATE(DATEVALUE(C13&"-01"),11),'📋 Транзакції'!$C$5:$C$3623,"<"&EDATE(DATEVALUE(C13&"-01"),12))>0,1,0) -> 0 | S13: =SUMIFS('📋 Транзакції'!$F$5:$F$3623,'📋 Транзакції'!$B$5:$B$3623,A13,'📋 Транзакції'!$C$5:$C$3623,">="&EDATE(DATEVALUE(C13&"-01"),0),'📋 Транзакції'!$C$5:$C$3623,"<"&EDATE(DATEVALUE(C13&"-01"),1)) -> 19.99 | T13: =SUMIFS('📋 Транзакції'!$F$5:$F$3623,'📋 Транзакції'!$B$5:$B$3623,A13,'📋 Транзакції'!$C$5:$C$3623,">="&EDATE(DATEVALUE(C13&"-01"),1),'📋 Транзакції'!$C$5:$C$3623,"<"&EDATE(DATEVALUE(C13&"-01"),2)) -> 19.99 | U13: =SUMIFS('📋 Транзакції'!$F$5:$F$3623,'📋 Транзакції'!$B$5:$B$3623,A13,'📋 Транзакції'!$C$5:$C$3623,">="&EDATE(DATEVALUE(C13&"-01"),2),'📋 Транзакції'!$C$5:$C$3623,"<"&EDATE(DATEVALUE(C13&"-01"),3)) -> 19.99 | V13: =SUMIFS('📋 Транзакції'!$F$5:$F$3623,'📋 Транзакції'!$B$5:$B$3623,A13,'📋 Транзакції'!$C$5:$C$3623,">="&EDATE(DATEVALUE(C13&"-01"),3),'📋 Транзакції'!$C$5:$C$3623,"<"&EDATE(DATEVALUE(C13&"-01"),4)) -> 19.99 | W13: =SUMIFS('📋 Транзакції'!$F$5:$F$3623,'📋 Транзакції'!$B$5:$B$3623,A13,'📋 Транзакції'!$C$5:$C$3623,">="&EDATE(DATEVALUE(C13&"-01"),4),'📋 Транзакції'!$C$5:$C$3623,"<"&EDATE(DATEVALUE(C13&"-01"),5)) -> 19.99 | X13: =SUMIFS('📋 Транзакції'!$F$5:$F$3623,'📋 Транзакції'!$B$5:$B$3623,A13,'📋 Транзакції'!$C$5:$C$3623,">="&EDATE(DATEVALUE(C13&"-01"),5),'📋 Транзакції'!$C$5:$C$3623,"<"&EDATE(DATEVALUE(C13&"-01"),6)) -> 19.99 | Y13: =SUMIFS('📋 Транзакції'!$F$5:$F$3623,'📋 Транзакції'!$B$5:$B$3623,A13,'📋 Транзакції'!$C$5:$C$3623,">="&EDATE(DATEVALUE(C13&"-01"),6),'📋 Транзакції'!$C$5:$C$3623,"<"&EDATE(DATEVALUE(C13&"-01"),7)) -> 19.99 | Z13: =SUMIFS('📋 Транзакції'!$F$5:$F$3623,'📋 Транзакції'!$B$5:$B$3623,A13,'📋 Транзакції'!$C$5:$C$3623,">="&EDATE(DATEVALUE(C13&"-01"),7),'📋 Транзакції'!$C$5:$C$3623,"<"&EDATE(DATEVALUE(C13&"-01"),8)) -> 19.99 | AA13: =SUMIFS('📋 Транзакції'!$F$5:$F$3623,'📋 Транзакції'!$B$5:$B$3623,A13,'📋 Транзакції'!$C$5:$C$3623,">="&EDATE(DATEVALUE(C13&"-01"),8),'📋 Транзакції'!$C$5:$C$3623,"<"&EDATE(DATEVALUE(C13&"-01"),9)) -> 19.99 | AB13: =SUMIFS('📋 Транзакції'!$F$5:$F$3623,'📋 Транзакції'!$B$5:$B$3623,A13,'📋 Транзакції'!$C$5:$C$3623,">="&EDATE(DATEVALUE(C13&"-01"),9),'📋 Транзакції'!$C$5:$C$3623,"<"&EDATE(DATEVALUE(C13&"-01"),10)) -> 0 | AC13: =SUMIFS('📋 Транзакції'!$F$5:$F$3623,'📋 Транзакції'!$B$5:$B$3623,A13,'📋 Транзакції'!$C$5:$C$3623,">="&EDATE(DATEVALUE(C13&"-01"),10),'📋 Транзакції'!$C$5:$C$3623,"<"&EDATE(DATEVALUE(C13&"-01"),11)) -> 0 | AD13: =SUMIFS('📋 Транзакції'!$F$5:$F$3623,'📋 Транзакції'!$B$5:$B$3623,A13,'📋 Транзакції'!$C$5:$C$3623,">="&EDATE(DATEVALUE(C13&"-01"),11),'📋 Транзакції'!$C$5:$C$3623,"<"&EDATE(DATEVALUE(C13&"-01"),12)) -> 0
A14: ='📋 Реєстрації'!A14:A615 -> U0641 | B14: {=INDEX('📋 Транзакції'!$C$5:$C$3623,MATCH(A14,'📋 Транзакції'!$B$5:$B$3623,0))} -> 45300 | C14: =TEXT(B14,"YYYY-MM") -> 2024-01 | D14: =COUNTIF('📋 Транзакції'!$B$5:$B$3623,A14) -> 16 | E14: =SUMIF('📋 Транзакції'!$B$5:$B$3623,A14,'📋 Транзакції'!$F$5:$F$3623) -> 299.85 | F14: =INT($A$1-MAXIFS('📋 Транзакції'!$C$5:$C$3623,'📋 Транзакції'!$B$5:$B$3623,A14)) -> 20 | G14: =IF(COUNTIFS('📋 Транзакції'!$B$5:$B$3623,A14,'📋 Транзакції'!$C$5:$C$3623,">="&EDATE(DATEVALUE(C14&"-01"),0),'📋 Транзакції'!$C$5:$C$3623,"<"&EDATE(DATEVALUE(C14&"-01"),1))>0,1,0) -> 1 | H14: =IF(COUNTIFS('📋 Транзакції'!$B$5:$B$3623,A14,'📋 Транзакції'!$C$5:$C$3623,">="&EDATE(DATEVALUE(C14&"-01"),1),'📋 Транзакції'!$C$5:$C$3623,"<"&EDATE(DATEVALUE(C14&"-01"),2))>0,1,0) -> 1 | I14: =IF(COUNTIFS('📋 Транзакції'!$B$5:$B$3623,A14,'📋 Транзакції'!$C$5:$C$3623,">="&EDATE(DATEVALUE(C14&"-01"),2),'📋 Транзакції'!$C$5:$C$3623,"<"&EDATE(DATEVALUE(C14&"-01"),3))>0,1,0) -> 1 | J14: =IF(COUNTIFS('📋 Транзакції'!$B$5:$B$3623,A14,'📋 Транзакції'!$C$5:$C$3623,">="&EDATE(DATEVALUE(C14&"-01"),3),'📋 Транзакції'!$C$5:$C$3623,"<"&EDATE(DATEVALUE(C14&"-01"),4))>0,1,0) -> 1 | K14: =IF(COUNTIFS('📋 Транзакції'!$B$5:$B$3623,A14,'📋 Транзакції'!$C$5:$C$3623,">="&EDATE(DATEVALUE(C14&"-01"),4),'📋 Транзакції'!$C$5:$C$3623,"<"&EDATE(DATEVALUE(C14&"-01"),5))>0,1,0) -> 1 | L14: =IF(COUNTIFS('📋 Транзакції'!$B$5:$B$3623,A14,'📋 Транзакції'!$C$5:$C$3623,">="&EDATE(DATEVALUE(C14&"-01"),5),'📋 Транзакції'!$C$5:$C$3623,"<"&EDATE(DATEVALUE(C14&"-01"),6))>0,1,0) -> 1 | M14: =IF(COUNTIFS('📋 Транзакції'!$B$5:$B$3623,A14,'📋 Транзакції'!$C$5:$C$3623,">="&EDATE(DATEVALUE(C14&"-01"),6),'📋 Транзакції'!$C$5:$C$3623,"<"&EDATE(DATEVALUE(C14&"-01"),7))>0,1,0) -> 1 | N14: =IF(COUNTIFS('📋 Транзакції'!$B$5:$B$3623,A14,'📋 Транзакції'!$C$5:$C$3623,">="&EDATE(DATEVALUE(C14&"-01"),7),'📋 Транзакції'!$C$5:$C$3623,"<"&EDATE(DATEVALUE(C14&"-01"),8))>0,1,0) -> 1 | O14: =IF(COUNTIFS('📋 Транзакції'!$B$5:$B$3623,A14,'📋 Транзакції'!$C$5:$C$3623,">="&EDATE(DATEVALUE(C14&"-01"),8),'📋 Транзакції'!$C$5:$C$3623,"<"&EDATE(DATEVALUE(C14&"-01"),9))>0,1,0) -> 1 | P14: =IF(COUNTIFS('📋 Транзакції'!$B$5:$B$3623,A14,'📋 Транзакції'!$C$5:$C$3623,">="&EDATE(DATEVALUE(C14&"-01"),9),'📋 Транзакції'!$C$5:$C$3623,"<"&EDATE(DATEVALUE(C14&"-01"),10))>0,1,0) -> 1 | Q14: =IF(COUNTIFS('📋 Транзакції'!$B$5:$B$3623,A14,'📋 Транзакції'!$C$5:$C$3623,">="&EDATE(DATEVALUE(C14&"-01"),10),'📋 Транзакції'!$C$5:$C$3623,"<"&EDATE(DATEVALUE(C14&"-01"),11))>0,1,0) -> 1 | R14: =IF(COUNTIFS('📋 Транзакції'!$B$5:$B$3623,A14,'📋 Транзакції'!$C$5:$C$3623,">="&EDATE(DATEVALUE(C14&"-01"),11),'📋 Транзакції'!$C$5:$C$3623,"<"&EDATE(DATEVALUE(C14&"-01"),12))>0,1,0) -> 1 | S14: =SUMIFS('📋 Транзакції'!$F$5:$F$3623,'📋 Транзакції'!$B$5:$B$3623,A14,'📋 Транзакції'!$C$5:$C$3623,">="&EDATE(DATEVALUE(C14&"-01"),0),'📋 Транзакції'!$C$5:$C$3623,"<"&EDATE(DATEVALUE(C14&"-01"),1)) -> 19.99 | T14: =SUMIFS('📋 Транзакції'!$F$5:$F$3623,'📋 Транзакції'!$B$5:$B$3623,A14,'📋 Транзакції'!$C$5:$C$3623,">="&EDATE(DATEVALUE(C14&"-01"),1),'📋 Транзакції'!$C$5:$C$3623,"<"&EDATE(DATEVALUE(C14&"-01"),2)) -> 19.99 | U14: =SUMIFS('📋 Транзакції'!$F$5:$F$3623,'📋 Транзакції'!$B$5:$B$3623,A14,'📋 Транзакції'!$C$5:$C$3623,">="&EDATE(DATEVALUE(C14&"-01"),2),'📋 Транзакції'!$C$5:$C$3623,"<"&EDATE(DATEVALUE(C14&"-01"),3)) -> 19.99 | V14: =SUMIFS('📋 Транзакції'!$F$5:$F$3623,'📋 Транзакції'!$B$5:$B$3623,A14,'📋 Транзакції'!$C$5:$C$3623,">="&EDATE(DATEVALUE(C14&"-01"),3),'📋 Транзакції'!$C$5:$C$3623,"<"&EDATE(DATEVALUE(C14&"-01"),4)) -> 19.99 | W14: =SUMIFS('📋 Транзакції'!$F$5:$F$3623,'📋 Транзакції'!$B$5:$B$3623,A14,'📋 Транзакції'!$C$5:$C$3623,">="&EDATE(DATEVALUE(C14&"-01"),4),'📋 Транзакції'!$C$5:$C$3623,"<"&EDATE(DATEVALUE(C14&"-01"),5)) -> 19.99 | X14: =SUMIFS('📋 Транзакції'!$F$5:$F$3623,'📋 Транзакції'!$B$5:$B$3623,A14,'📋 Транзакції'!$C$5:$C$3623,">="&EDATE(DATEVALUE(C14&"-01"),5),'📋 Транзакції'!$C$5:$C$3623,"<"&EDATE(DATEVALUE(C14&"-01"),6)) -> 19.99 | Y14: =SUMIFS('📋 Транзакції'!$F$5:$F$3623,'📋 Транзакції'!$B$5:$B$3623,A14,'📋 Транзакції'!$C$5:$C$3623,">="&EDATE(DATEVALUE(C14&"-01"),6),'📋 Транзакції'!$C$5:$C$3623,"<"&EDATE(DATEVALUE(C14&"-01"),7)) -> 19.99 | Z14: =SUMIFS('📋 Транзакції'!$F$5:$F$3623,'📋 Транзакції'!$B$5:$B$3623,A14,'📋 Транзакції'!$C$5:$C$3623,">="&EDATE(DATEVALUE(C14&"-01"),7),'📋 Транзакції'!$C$5:$C$3623,"<"&EDATE(DATEVALUE(C14&"-01"),8)) -> 19.99 | AA14: =SUMIFS('📋 Транзакції'!$F$5:$F$3623,'📋 Транзакції'!$B$5:$B$3623,A14,'📋 Транзакції'!$C$5:$C$3623,">="&EDATE(DATEVALUE(C14&"-01"),8),'📋 Транзакції'!$C$5:$C$3623,"<"&EDATE(DATEVALUE(C14&"-01"),9)) -> 19.99 | AB14: =SUMIFS('📋 Транзакції'!$F$5:$F$3623,'📋 Транзакції'!$B$5:$B$3623,A14,'📋 Транзакції'!$C$5:$C$3623,">="&EDATE(DATEVALUE(C14&"-01"),9),'📋 Транзакції'!$C$5:$C$3623,"<"&EDATE(DATEVALUE(C14&"-01"),10)) -> 19.99 | AC14: =SUMIFS('📋 Транзакції'!$F$5:$F$3623,'📋 Транзакції'!$B$5:$B$3623,A14,'📋 Транзакції'!$C$5:$C$3623,">="&EDATE(DATEVALUE(C14&"-01"),10),'📋 Транзакції'!$C$5:$C$3623,"<"&EDATE(DATEVALUE(C14&"-01"),11)) -> 19.99 | AD14: =SUMIFS('📋 Транзакції'!$F$5:$F$3623,'📋 Транзакції'!$B$5:$B$3623,A14,'📋 Транзакції'!$C$5:$C$3623,">="&EDATE(DATEVALUE(C14&"-01"),11),'📋 Транзакції'!$C$5:$C$3623,"<"&EDATE(DATEVALUE(C14&"-01"),12)) -> 19.99
