Workbook

Sheet Опис даних
A1: У цьому домашньому завданні ми будемо працювати з набором даних, який об’єднує показники щастя та економічної стабільності у 148 країнах за період з 2015 по 2023 рік. Цей датасет створено на основі Індексу світового щастя (World Happiness Index, WHI) та макроекономічних показників, таких як ВВП і інфляція. Дані розміщено на аркуші "Сирі дані", опис колонок даних - на аркуші "Опис колонок даних". Незаповнені клітинки містять відсутні дані для перетину цього рядочку і колонки. Мета використання набору — дослідити, як економічні умови впливають на добробут і щастя людей в різних регіонах світу. А наша з вами додаткова мета — попрактикуватись із статистичним аналізом даних. І для цього ми будемо виконувати завдання на аркуші "Завдання".

Sheet Опис колонок даних
A1: Назва змінної | B1: Опис
A2: Country | B2: Назва країни, в якій були зафіксовані дані.
A3: Continent/Region | B3: Континент або регіон, у якому розташована країна.
A4: Year | B4: Рік, у якому були зібрані дані.
A5: Happiness Score | B5: Індекс щастя за World Happiness Report: чим вище значення, тим вищий рівень щастя.
A6: GDP per Capita | B6: Нормалізований валовий внутрішній продукт (ВВП) на душу населення.
A7: Headline Consumer Price Inflation | B7: Загальний рівень інфляції на основі індексу споживчих цін (CPI).
A8: Energy Consumer Price Inflation | B8: Рівень інфляції на енергетичні товари згідно з індексом споживчих цін.
A9: Food Consumer Price Inflation | B9: Рівень інфляції на продукти харчування згідно з індексом споживчих цін.
A10: Official Core Consumer Price Inflation | B10: Базовий рівень інфляції без урахування енергії та продуктів харчування.
A11: Producer Price Inflation | B11: Рівень інфляції на основі індексу цін виробників (PPI).
A12: GDP deflator Index growth rate | B12: Темп зростання дефлятора ВВП — показника загального рівня цін в економіці.
... A17: Perceptions of corruption | B17: Сприйняття рівня корупції в країні за оцінками її мешканців.

Sheet Завдання
A1: Завдання: 1. Створіть новий аркуш “Statistics” і обчисліть на ньому описову статистику показників Happiness Score, GDP per Capita. А саме, обчисліть значення - Арифметичного середнього - Медіани - Макс. Значення - Мін. Значення - Діапазон (Range) - Дисперсії - Стандартного відхилення Округліть всі значення до 2х цифр після коми 2. Напишіть на аркуші “Statistics” свої висновки: що ми можете сказати про розподіл розглянутих числових колонок Чи розподіл кожної з колонок симетричний? 3. На аркуші “Statistics” побудуйте гістограми розподілів числових колонок Happiness Score, GDP per Capita. Опишіть, що бачите з розподілів? Які аналітичні висновки ви б могли відзвітувати про ці дані? 4. На аркуші “Statistics” побудуйте графік розсіювання Happiness Score проти GDP per Capita. Опишіть, що ви бачите на графіку, чи є щось цікавое і незвичне? 5. Обчисліть коефіцієнт кореляції Пірсона між Happiness Score, GDP per Capita. Для обчислення використайте фукнцію PEARSON(). Напишіть висновок про те значення, яке отримали. Що це каже про дані? 6. Обчисліть кореляціяю Пірсона між Happiness Score і всіма рештою числовими значеннями, які потенційно на нього впливають. З яким показником найсильніший лінійний звʼязок у Happiness Score? Чи для вас це виглядає логічним? 7. Запишіть коротке відео використовуючи зручний онлайн сервіс Loom, на якому опишіть свої аналітичні висновки із презентацією результатів. Українською, але якщо хочете спробувати анлійською аби потренуватись - you are welcome. Це - обовʼязковий пункт цього завдання. На презентації має бути видно вас, видно екран і чути, як ви презентуєте результати невеличного дослідження. Відео оцінюється в 2 бали. оцінюємо інформативність, зрозумілість і загальне враження (чи все чисто і охайно як в звіті, так і на відео, чи добре вас видно).

Sheet Сирі дані
A1: Country | B1: Continent/Region | C1: Year | D1: Happiness Score | E1: GDP per Capita | F1: Headline Consumer Price Inflation | G1: Energy Consumer Price Inflation | H1: Food Consumer Price Inflation | I1: Official Core Consumer Price Inflation | J1: Producer Price Inflation | K1: GDP deflator Index growth rate | L1: Social support | M1: Healthy life expectancy at birth | N1: Freedom to make life choices | O1: Generosity | P1: Perceptions of corruption
A2: Afghanistan | B2: South Asia | C2: 2015 | D2: 3.575 | E2: 0.31982 | F2: -0.66000003 | G2: -4.25 | H2: -0.83999997 | I2: 0.21999912 | K2: 2.6650903 | L2: 0.30285 | M2: 0.30335 | N2: 0.23414 | O2: 0.3651 | P2: 0.09719
A3: Afghanistan | B3: South Asia | C3: 2016 | D3: 3.36 | E3: 0.38227 | F3: 4.3800001 | G3: 2.0699999 | H3: 5.6700001 | I3: 5.1927602 | K3: -2.4095092 | L3: 0.11037 | M3: 0.17344 | N3: 0.1643 | O3: 0.31268 | P3: 0.07112
A4: Afghanistan | B4: South Asia | C4: 2017 | D4: 3.7939999 | E4: 0.40147722 | F4: 4.976 | G4: 4.4400001 | H4: 6.9400001 | I4: 5.4232275 | K4: 2.404 | L4: 0.58154333 | M4: 0.18074678 | N4: 0.10617952 | O4: 0.31187093 | P4: 0.06115783
A5: Afghanistan | B5: South Asia | C5: 2018 | D5: 3.632 | E5: 0.332 | F5: 0.63 | G5: 1.4741849 | H5: -1.0459524 | I5: -0.12603251 | K5: 2.0712082 | L5: 0.537 | M5: 0.255 | N5: 0.085 | O5: 0.191 | P5: 0.036
A6: Afghanistan | B6: South Asia | C6: 2019 | D6: 3.203 | E6: 0.35 | F6: 2.302 | G6: -2.4943588 | H6: 3.7947702 | K6: 6.520928 | L6: 0.517 | M6: 0.361 | N6: 0 | O6: 0.158 | P6: 0.025
A7: Afghanistan | B7: South Asia | C7: 2020 | D7: 2.5669 | E7: 0.30070585 | F7: 5.4429998 | H7: 5.8290052 | K7: 5.3071196 | L7: 0.35643384 | M7: 0.26605153 | N7: 0 | O7: 0.13523471 | P7: 0.001225785
A8: Afghanistan | B8: South Asia | C8: 2021 | D8: 2.523 | E8: 0.37 | F8: 5.062 | K8: 0.52451652 | L8: 0 | M8: 0.126 | N8: 0 | O8: 0.122 | P8: 0.01
A9: Afghanistan | B9: South Asia | C9: 2022 | D9: 2.404 | E9: 0.758 | F9: 10.6 | K9: 5.4750714 | L9: 0 | M9: 0.289 | N9: 0 | O9: 0.089 | P9: 0.005
A10: Afghanistan | B10: South Asia | C10: 2023 | D10: 1.859 | E10: 0.645 | L10: 0 | M10: 0.087 | N10: 0 | O10: 0.093 | P10: 0.059
A11: Albania | B11: Central and Eastern Europe | C11: 2015 | D11: 4.959 | E11: 0.87867 | F11: 1.9101791 | G11: -0.51999998 | H11: 4.3194895 | I11: -0.15695719 | K11: 0.5642782 | L11: 0.80434 | M11: 0.81325 | N11: 0.35733 | O11: 0.14272 | P11: 0.06413
A12: Albania | B12: Central and Eastern Europe | C12: 2016 | D12: 4.655 | E12: 0.9553 | F12: 1.2912338 | G12: 0.039999999 | H12: 3.2491877 | I12: 0.15138157 | J12: -1.6133035 | K12: -0.63240499 | L12: 0.50163 | M12: 0.73007 | N12: 0.31866 | O12: 0.1684 | P12: 0.05301
A13: Albania | B13: Central and Eastern Europe | C13: 2017 | D13: 4.6440001 | E13: 0.99619275 | F13: 1.987 | G13: 1 | H13: 3.9054298 | I13: 0.819713 | J13: 2.8422458 | K13: 1.4509361 | L13: 0.80368525 | M13: 0.73115975 | N13: 0.38149863 | O13: 0.20131294 | P13: 0.039864216
A14: Albania | B14: Central and Eastern Europe | C14: 2018 | D14: 4.586 | E14: 0.916 | F14: 2.03 | G14: 2.8 | H14: 2.6714315 | I14: 0.92837429 | J14: 1.602622 | K14: 1.3594644 | L14: 0.817 | M14: 0.79 | N14: 0.419 | O14: 0.149 | P14: 0.032
A15: Albania | B15: Central and Eastern Europe | C15: 2019 | D15: 4.719 | E15: 0.947 | F15: 1.411 | G15: 0.68900985 | H15: 2.911938 | I15: 0.73537815 | J15: -0.79672098 | K15: 0.36341733 | L15: 0.848 | M15: 0.874 | N15: 0.383 | O15: 0.178 | P15: 0.027
A16: Albania | B16: Central and Eastern Europe | C16: 2020 | D16: 4.8827 | E16: 0.90665305 | F16: 1.6208866 | G16: 1.4200893 | H16: 3.6074543 | I16: 1.4114063 | J16: -3.4326388 | K16: 1.4133958 | L16: 0.83048391 | M16: 0.84632963 | N16: 0.46194589 | O16: 0.17102776 | P16: 0.025361285
A17: Albania | B17: Central and Eastern Europe | C17: 2021 | D17: 5.117 | E17: 1.008 | F17: 2.0414716 | G17: 2.7 | H17: 3.9 | I17: 1.6793293 | J17: 2.6989083 | K17: 5.9280138 | L17: 0.529 | M17: 0.646 | N17: 0.491 | O17: 0.168 | P17: 0.024
A18: Albania | B18: Central and Eastern Europe | C18: 2022 | D18: 5.199 | E18: 1.439 | F18: 6.7252027 | G18: 14.216085 | H18: 11.203514 | I18: 6.501041 | J18: 19.937537 | K18: 9.6517633 | L18: 0.646 | M18: 0.719 | N18: 0.511 | O18: 0.138 | P18: 0.028
A19: Albania | B19: Central and Eastern Europe | C19: 2023 | D19: 5.277 | E19: 1.449 | F19: 5.5652239 | G19: -5.0686364 | I19: 5.2225313 | K19: 5.1942693 | L19: 0.951 | M19: 0.48 | N19: 0.549 | O19: 0.133 | P19: 0.037
A20: Algeria | B20: Middle East and North Africa | C20: 2015 | D20: 5.605 | E20: 0.93929 | F20: 4.3916664 | G20: 1.7503198 | H20: 3.604882 | J20: 2.2497056 | K20: -6.4556358 | L20: 1.07772 | M20: 0.61766 | N20: 0.28579 | O20: 0.07822 | P20: 0.17383
A21: Algeria | B21: Middle East and North Africa | C21: 2016 | D21: 6.355 | E21: 1.05266 | F21: 5.8003039 | G21: 5.9810543 | H21: 2.6168447 | J21: 4.1193409 | K21: 1.5487295 | L21: 0.83309 | M21: 0.61804 | N21: 0.21006 | O21: 0.07044 | P21: 0.16157
A22: Algeria | B22: Middle East and North Africa | C22: 2017 | D22: 5.8720002 | E22: 1.0918645 | F22: 5.591 | G22: 2.8017797 | H22: 5.6054001 | J22: 1.8786095 | K22: 6.3908369 | L22: 1.1462175 | M22: 0.61758465 | N22: 0.23333581 | O22: 0.069436647 | P22: 0.14609611
A23: Algeria | B23: Middle East and North Africa | C23: 2018 | D23: 5.295 | E23: 0.979 | F23: 3.51 | G23: 1.2388263 | H23: 1.7412293 | J23: 4.0810566 | K23: 7.0647866 | L23: 1.154 | M23: 0.687 | N23: 0.077 | O23: 0.055 | P23: 0.135
A24: Algeria | B24: Middle East and North Africa | C24: 2019 | D24: 5.211 | E24: 1.002 | F24: 1.952 | G24: 1.425144 | H24: 0.64319569 | J24: 2.6372888 | K24: -0.90998946 | L24: 1.16 | M24: 0.785 | N24: 0.086 | O24: 0.073 | P24: 0.114
A25: Algeria | B25: Middle East and North Africa | C25: 2020 | D25: 5.0050998 | E25: 0.943856 | F25: 2.4151309 | G25: 1.3897383 | H25: 0.22050305 | K25: -4.6866948 | L25: 1.1430036 | M25: 0.74541855 | N25: 0.083943799 | O25: 0.11891501 | P25: 0.12919065
A26: Algeria | B26: Middle East and North Africa | C26: 2021 | D26: 4.887 | E26: 0.946 | F26: 7.2260631 | G26: 1.47 | H26: 10.13 | J26: 7.4329045 | K26: 15.736744 | L26: 0.765 | M26: 0.552 | N26: 0.119 | O26: 0.144 | P26: 0.12
A27: Algeria | B27: Middle East and North Africa | C27: 2022 | D27: 5.122 | E27: 1.363 | F27: 9.2655155 | G27: 2.4020968 | H27: 12.7019 | K27: 15.567649 | L27: 0.97 | M27: 0.643 | N27: 0.146 | O27: 0.106 | P27: 0.15
A28: Algeria | B28: Middle East and North Africa | C28: 2023 | D28: 5.329 | E28: 1.353 | F28: 9.3221738 | G28: 1.4879778 | H28: 13.256373 | K28: -0.42962924 | L28: 1.298 | M28: 0.409 | N28: 0.252 | O28: 0.073 | P28: 0.152
A29: Angola | B29: Sub-Saharan Africa | C29: 2015 | D29: 4.033 | E29: 0.75778 | F29: 9.1590004 | H29: 9.2964697 | J29: 9.1711226 | K29: -3.5183903 | L29: 0.8604 | M29: 0.16683 | N29: 0.10384 | O29: 0.12344 | P29: 0.07122
A30: Angola | B30: Sub-Saharan Africa | C30: 2016 | D30: 3.866 | E30: 0.84731 | F30: 32.377731 | H30: 21.2355 | J30: 20.392229 | K30: 21.7743 | L30: 0.66366 | M30: 0.04991 | N30: 0.00589 | O30: 0.12071 | P30: 0.08434
A31: Angola | B31: Sub-Saharan Africa | C31: 2017 | D31: 3.7950001 | E31: 0.85842818 | F31: 29.844 | H31: 40.986217 | J31: 23.023481 | K31: 22.617828 | L31: 1.104412 | M31: 0.049868666 | N31: 0 | O31: 0.09792649 | P31: 0.069720335
A32: Angola | B32: Sub-Saharan Africa | C32: 2018 | D32: 3.795 | E32: 0.73 | F32: 19.63 | H32: 22.350267 | J32: 16.090868 | K32: 33.762011 | L32: 1.125 | M32: 0.269 | N32: 0 | O32: 0.079 | P32: 0.061
A33: Argentina | B33: Latin America and Caribbean | C33: 2015 | D33: 6.574 | E33: 1.05351 | F33: 26.538401 | K33: 26.579992 | L33: 1.24823 | M33: 0.78723 | N33: 0.44974 | O33: 0.11451 | P33: 0.08484
A34: Argentina | B34: Latin America and Caribbean | C34: 2016 | D34: 6.65 | E34: 1.15137 | F34: 39.400002 | H34: 49.432299 | K34: 41.119381 | L34: 1.06612 | M34: 0.69711 | N34: 0.42284 | O34: 0.10989 | P34: 0.07296
A35: Argentina | B35: Latin America and Caribbean | C35: 2017 | D35: 6.599 | E35: 1.1852955 | F35: 25.675 | H35: 20.36 | J35: 16.26404 | K35: 26.006378 | L35: 1.4404511 | M35: 0.69513708 | N35: 0.4945192 | O35: 0.10945706 | P35: 0.059739888
A36: Argentina | B36: Latin America and Caribbean | C36: 2018 | D36: 6.388 | E36: 1.073 | F36: 34.28 | G36: 52.759998 | H36: 32.738937 | J36: 52.216434 | K36: 40.012154 | L36: 1.468 | M36: 0.744 | N36: 0.57 | O36: 0.062 | P36: 0.054
A37: Argentina | B37: Latin America and Caribbean | C37: 2019 | D37: 6.086 | E37: 1.092 | F37: 53.548 | G37: 49.280769 | H37: 58.344105 | J37: 58.310783 | K37: 50.622581 | L37: 1.432 | M37: 0.881 | N37: 0.471 | O37: 0.066 | P37: 0.05
A38: Argentina | B38: Latin America and Caribbean | C38: 2020 | D38: 5.9747 | E38: 1.0284656 | F38: 42.015095 | G38: 19.946911 | H38: 46.970287 | J38: 42.507 | K38: 39.840848 | L38: 1.3725437 | M38: 0.84977371 | N38: 0.52084035 | O38: 0.070100471 | P38: 0.060415059
A39: Argentina | B39: Latin America and Caribbean | C39: 2021 | D39: 5.929 | E39: 1.162 | F39: 48.40938 | G39: 26.23 | H39: 49.846 | J39: 59.085495 | K39: 54.152412 | L39: 0.98 | M39: 0.646 | N39: 0.544 | O39: 0.069 | P39: 0.067
A40: Argentina | B40: Latin America and Caribbean | C40: 2022 | D40: 5.967 | E40: 1.592 | F40: 72.43076 | G40: 51.398287 | H40: 74.63056 | J40: 60.273346 | K40: 41.066531 | L40: 1.102 | M40: 0.662 | N40: 0.555 | O40: 0.081 | P40: 0.085
...

Sheet Statistics
A1: Описова статистика показників Happiness Score, GDP per Capita
B3: Happiness Score | C3: GDP per Capita
A4: Арифметичне середнє | B4: =AVERAGE('Сирі дані'!D2:D1233) -> 5.4990006 | C4: =AVERAGE('Сирі дані'!E2:E1233) -> 1.0307665
A5: Медіана | B5: =MEDIAN('Сирі дані'!D2:D1233) -> 5.5389499 | C5: =MEDIAN('Сирі дані'!E2:E1233) -> 1.0515
A6: Мода | B6: =MODE('Сирі дані'!D2:D1233) -> 6.125 | C6: =MODE('Сирі дані'!E2:E1233) -> 0
A7: Min | B7: =MIN('Сирі дані'!D2:D1233) -> 1.859 | C7: =MIN('Сирі дані'!E2:E1233) -> 0
A8: Max | B8: =MAX('Сирі дані'!D2:D1233) -> 7.842 | C8: =MAX('Сирі дані'!E2:E1233) -> 2.209
A9: Діапазон | B9: =MAX(B8)-MIN(B7) -> 5.983 | C9: =MAX(C8)-MIN(C7) -> 2.209
A10: Дисперсія | B10: =VAR('Сирі дані'!D2:D1233) -> 1.2888213 | C10: =VAR('Сирі дані'!E2:E1233) -> 0.20451223
A11: Ст. відх. | B11: =STDEV('Сирі дані'!D2:D1233) -> 1.1352626 | C11: =STDEV('Сирі дані'!E2:E1233) -> 0.45223029
A13: Висновки: | B13: Для обох показників медіана зміщена праворуч, що важливо, бо вона не чутлива до викидів, які могли зменшити значення для середнього. Мода для Happiness Score помітно вища за середні показники, що говорить про переважання вищих рівнів щастя для більшості країн. Широкий діапазон розкиду даних показує помітну варіативність рівня щастя між країнами, і так само - суттєве розсіювання для показника ВВП. Дисперсія для Happiness Score та GDP per Capita не є великою, тобто їх значення доволі скупчені навколо середнього. А стандартне відхилення каже, що варіація даних невелика, проте для індексу щастя вона трохи більша, аніж для ВВП, як і було видно з дисперсії.
A39: Висновки: | B39: Гістограми підтвердили попередні висновки. Значення індексу щастя на гістограмі зміщені праворуч -це означає меншу кількість країн з низьким індексом щастя. Гісторгама для ВВП навпаки зміщена ліворуч - менша кількість країн з дуже високим ВВП на душу населення. Тобто значення для індексу щастя тяжіють до більших величин, а от ВВП до менших. Хоча саме дуже низькі чи дуже високі значення (крайні значення) все ж зустрічаються рідше і для більшості країн характерні середні показники (наявна центральна тенденція).
A64: Висновки: | B64: Графік розсіювання демонструє наявність позитивного зв'язку між індексом щастя та ВВП. Можна сказати що іпроглядається певна тенденція — країни з вищим ВВП мають і вищий рівень щастя, що може свідчити про вплив економічного добробуту на відчуття благополуччя. Хоча трапляються окремі країни, які мають високий рівень щастя при невисокому ВВП, що свідчить про вплив нематеріальних факторів.
A69: коефіцієнт кореляції Пірсона між Happiness Score, GDP per Capita
A70: PEARSON() | B70: =PEARSON('Сирі дані'!$D$2:$D$1233, 'Сирі дані'!$E$2:$E$1233) -> 0.73968268
A72: Висновки: | B72: Оскільки кореляція Пірсона показує силу і напрямок зв'язку між 2 змінними ми тепер знаємо що між Happiness Score та GDP per Capita наявний сильний, прямий зв'язок. Але коефіцієнт таки не =1, тому можемо припускати, що окрім економічного фактору вплив на індекс щастя мають інші чинники.
A76: коефіцієнт кореляції Пірсона між Happiness Score та рештою показників:
A77: Headline Consumer Price Inflation | B77: =PEARSON('Сирі дані'!$D$2:$D$1233, 'Сирі дані'!$F$2:$F$1233) -> -0.19993888
A78: Energy Consumer Price Inflation | B78: =PEARSON('Сирі дані'!$D$2:$D$1233, 'Сирі дані'!$G$2:$G$1233) -> -0.13505193
A79: Food Consumer Price Inflation | B79: =PEARSON('Сирі дані'!$D$2:$D$1233, 'Сирі дані'!$H$2:$H$1233) -> -0.17171207
A80: Official Core Consumer Price Inflation | B80: =PEARSON('Сирі дані'!$D$2:$D$1233, 'Сирі дані'!$I$2:$I$1233) -> -0.22461333
A81: Producer Price Inflation | B81: =PEARSON('Сирі дані'!$D$2:$D$1233, 'Сирі дані'!$J$2:$J$1233) -> -0.07830013
A82: GDP deflator Index growth rate | B82: =PEARSON('Сирі дані'!$D$2:$D$1233, 'Сирі дані'!$K$2:$K$1233) -> -0.14387409
A83: Social support | B83: =PEARSON('Сирі дані'!$D$2:$D$1233, 'Сирі дані'!$L$2:$L$1233) -> 0.65757506
A84: Healthy life expectancy at birth | B84: =PEARSON('Сирі дані'!$D$2:$D$1233, 'Сирі дані'!$M$2:$M$1233) -> 0.70242203
A85: Freedom to make life choices | B85: =PEARSON('Сирі дані'!$D$2:$D$1233, 'Сирі дані'!$N$2:$N$1233) -> 0.56572299
A86: Generosity | B86: =PEARSON('Сирі дані'!$D$2:$D$1233, 'Сирі дані'!$O$2:$O$1233) -> 0.098285261
A87: Perceptions of corruption | B87: =PEARSON('Сирі дані'!$D$2:$D$1233, 'Сирі дані'!$P$2:$P$1233) -> 0.4364281
A89: Висновки: | B89: Група показників (Headline Consumer Price Inflation, Energy Consumer Price Inflation, Food Consumer Price Inflation, Official Core Consumer Price Inflation, Producer Price Inflation, GDP deflator Index growth rate) має обернений зв'язок із Happiness Score. Узагальнено цей зв'язок не надто суттєвий для всіх цих показників. При цьому найслабший із них - на індекс цін виробників, а найбільший - із Базовим рівнем інфляції без урахування енергії та продуктів харчування. 2 група показників які мають прямий зв'язок із Happiness Score: (Social support, Healthy life expectancy at birth, Freedom to make life choices, Generosity, Perceptions of corruption). На відміну від попередньої групи тут видно тісніші взщі взаємозв'язки. Виділяється лише Рівень щедрості в країні, який з індексом щастя майже не повязаний. А от найбільша кореляція виявилась між Індексом щастя та Очікуваною нормалізованою тривалістю здорового життя при народженні, та трохи менша із значенням Рівня соціальної підтримки, яку отримують громадяни від держави та сім’ї. ОТЖЕ, ми побачили, що вцілому Індекс щастя слабо пов'язаний із суто фінансовими показниками - як рівень інфляції чи то загальний рівень цін, але прямо і сильно корелює із більш соціально орієнтованими показниками на зразок соціальної підтримки та очікуваної тривалості життя.
A101: ВИСНОВКИ: | B101: Проведений аналіз показав, що між рівнем щастя та о-вними макроекономічними показниками існує лише частковий зв’язок. Хоча зростання ВВП на душу населення супроводжується підвищенням індексу щастя, економічне зростання не гарантує відчуття благополуччя. Найвагомішу роль відіграють все ж соціальні чинники — соціальна підтримка, свобода вибору та здоров’я. Саме вони забезпечують позитивний вплив на рівень щастя, а не фінансові показники.
A106: ВІДЕО
A107: https://www.loom.com/share/d73b5491c7c74f43b1a5d399f7459f1b
