Workbook

Sheet Опис даних
A1: У цьому домашньому завданні ми будемо працювати з набором даних, який об’єднує показники щастя та економічної стабільності у 148 країнах за період з 2015 по 2023 рік. Цей датасет створено на основі Індексу світового щастя (World Happiness Index, WHI) та макроекономічних показників, таких як ВВП і інфляція. Посилання на джерело даних: https://www.kaggle.com/datasets/agrafintech/world-happiness-index-and-inflation-dataset Увага! Дані в джерелі могли оновлюватись. У нас - перша версія цих даних. Дані розміщено на аркуші Raw. Мета використання набору — дослідити, як економічні умови впливають на добробут і щастя людей в різних регіонах світу. А наша з вами додаткова мета — попрактикуватись із статистичним аналізом даних. Вміст набору даних Набір даних наданий у форматі CSV і містить 17 колонок, які охоплюють: - Індекс щастя та рейтинг: - Happiness Score – загальний бал щастя - Happiness Rank – місце країни у світовому рейтингу щастя - Економічні показники: - GDP per capita – ВВП на душу населення - Inflation – рівень інфляції - Corruption Perception – сприйняття корупції - Соціальні чинники: - Freedom – рівень свободи - Social Support – підтримка з боку суспільства - Generosity – рівень щедрості - Географічна інформація: - Country – назва країни - Continent – континент, до якого належить країна - Year – рік спостереження

Sheet Завдання
A1: Завдання: 1. Створіть новий аркуш “Distribution check” На цьому аркуші побудуйте гістограми для трьох показників: - Social support - Freedom to make life choices - Perceptions of corruption На основі побудованих гістограм: - Зробіть припущення: чи схожий розподіл кожного з показників на нормальний? - Обґрунтуйте свої припущення у вигляді короткого текстового висновку під кожною гістограмою або на окремому аркуші "Аналітичні висновки". 2. Проведіть формальну перевірку нормальності розподілу для кожного показника Для цього використайте: - QQ plot - Обчисліть коефіцієнти Skewness (асиметрія) та Kurtosis (ексцес) для кожного показника. На основі отриманих графіків і чисел напишіть аналітичні висновки: - Чи підтверджують ці методи ваші припущення з попереднього пункту? - Чи можна вважати кожен показник нормально розподіленим? Оцінка за пункт — 3 бали 3. На який розподіл на ваш погляд схожий розподіл Perceptions of corruption? Як гадаєте, чому цей показник розподілений саме так?

Sheet Raw
A1: Country | B1: Year | C1: Happiness Rank | D1: Happiness Score | E1: GDP per Capita | F1: Social support | G1: Healthy life expectancy at birth | H1: Freedom to make life choices | I1: Generosity | J1: Perceptions of corruption | K1: Energy Consumer Price Inflation | L1: Food Consumer Price Inflation | M1: GDP deflator Index growth rate | N1: Headline Consumer Price Inflation | O1: Official Core Consumer Price Inflation | P1: Producer Price Inflation | Q1: Continent | S1: SORT_Social support | T1: Rank_Freedom | U1: Rank_Corruption | V1: Rank_Social support | W1: Rank_Freedom | X1: Rank_Corruption
A2: Afghanistan | B2: 2015 | C2: 153 | D2: 3.575 | E2: 0.31982 | F2: 0.30285 | G2: 0.30335 | H2: 0.23414 | I2: 0.3651 | J2: 0.09719 | K2: -4.25 | L2: -0.83999997 | M2: 2.6650903 | N2: -0.66000003 | O2: 0.21999912 | Q2: Asia | S2: {=SORT(F$2:F$1204)} -> 0 | T2: {=SORT(H$2:H$1204)} -> 0 | U2: {=SORT(J$2:J$1204)} -> 0
A3: Afghanistan | B3: 2016 | C3: 154 | D3: 3.36 | E3: 0.38227 | F3: 0.11037 | G3: 0.17344 | H3: 0.1643 | I3: 0.31268 | J3: 0.07112 | K3: 2.0699999 | L3: 5.6700001 | M3: -2.4095092 | N3: 4.3800001 | O3: 5.1927602 | Q3: Asia | S3: 0 | T3: 0 | U3: 0
A4: Afghanistan | B4: 2017 | C4: 141 | D4: 3.7939999 | E4: 0.40147722 | F4: 0.58154333 | G4: 0.18074678 | H4: 0.10617952 | I4: 0.31187093 | J4: 0.06115783 | K4: 4.4400001 | L4: 6.9400001 | M4: 2.404 | N4: 4.976 | O4: 5.4232275 | Q4: Asia | S4: 0 | T4: 0 | U4: 0
A5: Afghanistan | B5: 2018 | C5: 145 | D5: 3.632 | E5: 0.332 | F5: 0.537 | G5: 0.255 | H5: 0.085 | I5: 0.191 | J5: 0.036 | K5: 1.4741849 | L5: -1.0459524 | M5: 2.0712082 | N5: 0.63 | O5: -0.12603251 | Q5: Asia | S5: 0 | T5: 0 | U5: 0
A6: Afghanistan | B6: 2019 | C6: 154 | D6: 3.203 | E6: 0.35 | F6: 0.517 | G6: 0.361 | H6: 0 | I6: 0.158 | J6: 0.025 | K6: -2.4943588 | L6: 3.7947702 | M6: 6.520928 | N6: 2.302 | Q6: Asia | S6: 0 | T6: 0 | U6: 0
A7: Afghanistan | B7: 2020 | C7: 153 | D7: 2.5669 | E7: 0.30070585 | F7: 0.47036695 | G7: 52.59 | H7: 0.39657301 | I7: -0.0964294 | J7: 0.93368655 | L7: 5.8290052 | M7: 5.3071196 | N7: 5.4429998 | Q7: Asia | S7: 0 | T7: 0 | U7: 0
A8: Afghanistan | B8: 2021 | C8: 149 | D8: 2.523 | E8: 7.695 | F8: 0.463 | G8: 52.493 | H8: 0.382 | I8: -0.102 | J8: 0.924 | M8: 0.52451652 | N8: 5.062 | Q8: Asia | S8: 0.064 | T8: 0.00589 | U8: 0
A9: Afghanistan | B9: 2022 | C9: 146 | D9: 2.404 | E9: 0.758 | F9: 0 | G9: 0.289 | H9: 0 | I9: 0.089 | J9: 0.005 | M9: 5.4750714 | N9: 10.6 | Q9: Asia | S9: 0.10419 | T9: 0.01 | U9: 0.001
A10: Afghanistan | B10: 2023 | C10: 137 | D10: 1.859 | E10: 7.324 | F10: 0.341 | G10: 54.712 | H10: 0.382 | I10: -0.081 | J10: 0.847 | Q10: Asia | S10: 0.11037 | T10: 0.014995855 | U10: 0.00227
A11: Albania | B11: 2015 | C11: 95 | D11: 4.959 | E11: 0.87867 | F11: 0.80434 | G11: 0.81325 | H11: 0.35733 | I11: 0.14272 | J11: 0.06413 | K11: -0.51999998 | L11: 4.3194895 | M11: 0.5642782 | N11: 1.9101791 | O11: -0.15695719 | Q11: Europe | S11: 0.13995 | T11: 0.016 | U11: 0.00322
A12: Albania | B12: 2016 | C12: 109 | D12: 4.655 | E12: 0.9553 | F12: 0.50163 | G12: 0.73007 | H12: 0.31866 | I12: 0.1684 | J12: 0.05301 | K12: 0.039999999 | L12: 3.2491877 | M12: -0.63240499 | N12: 1.2912338 | O12: 0.15138157 | P12: -1.6133035 | Q12: Europe | S12: 0.147 | T12: 0.025 | U12: 0.004
A13: Albania | B13: 2017 | C13: 109 | D13: 4.6440001 | E13: 0.99619275 | F13: 0.80368525 | G13: 0.73115975 | H13: 0.38149863 | I13: 0.20131294 | J13: 0.039864216 | K13: 1 | L13: 3.9054298 | M13: 1.4509361 | N13: 1.987 | O13: 0.819713 | P13: 2.8422458 | Q13: Europe | S13: 0.18519 | T13: 0.026 | U13: 0.004387901
A14: Albania | B14: 2018 | C14: 112 | D14: 4.586 | E14: 0.916 | F14: 0.817 | G14: 0.79 | H14: 0.419 | I14: 0.149 | J14: 0.032 | K14: 2.8 | L14: 2.6714315 | M14: 1.3594644 | N14: 2.03 | O14: 0.92837429 | P14: 1.602622 | Q14: Europe | S14: 0.19249 | T14: 0.030369857 | U14: 0.005
A15: Albania | B15: 2019 | C15: 107 | D15: 4.719 | E15: 0.947 | F15: 0.848 | G15: 0.874 | H15: 0.383 | I15: 0.178 | J15: 0.027 | K15: 0.68900985 | L15: 2.911938 | M15: 0.36341733 | N15: 1.411 | O15: 0.73537815 | P15: -0.79672098 | Q15: Europe | S15: 0.23442 | T15: 0.0432 | U15: 0.005
A16: Albania | B16: 2020 | C16: 105 | D16: 4.8827 | E16: 0.90665305 | F16: 0.67107046 | G16: 68.708138 | H16: 0.78199422 | I16: -0.042309489 | J16: 0.89630371 | K16: 1.4200893 | L16: 3.6074543 | M16: 1.4133958 | N16: 1.6208866 | O16: 1.4114063 | P16: -3.4326388 | Q16: Europe | S16: 0.24749 | T16: 0.05822 | U16: 0.006
A17: Albania | B17: 2021 | C17: 93 | D17: 5.117 | E17: 9.52 | F17: 0.697 | G17: 68.999 | H17: 0.785 | I17: -0.03 | J17: 0.901 | K17: 2.7 | L17: 3.9 | M17: 5.9280138 | N17: 2.0414716 | O17: 1.6793293 | P17: 2.6989083 | Q17: Europe | S17: 0.26135 | T17: 0.059900753 | U17: 0.006
A18: Albania | B18: 2022 | C18: 90 | D18: 5.199 | E18: 1.439 | F18: 0.646 | G18: 0.719 | H18: 0.511 | I18: 0.138 | J18: 0.028 | K18: 14.216085 | L18: 11.203514 | M18: 9.6517633 | N18: 6.7252027 | O18: 6.501041 | P18: 19.937537 | Q18: Europe | S18: 0.268 | T18: 0.065 | U18: 0.006
A19: Albania | B19: 2023 | C19: 83 | D19: 5.277 | E19: 9.567 | F19: 0.718 | G19: 69.15 | H19: 0.794 | I19: -0.007 | J19: 0.878 | K19: -5.0686364 | M19: 5.1942693 | N19: 5.5652239 | O19: 5.2225313 | Q19: Europe | S19: 0.279 | T19: 0.066 | U19: 0.006
A20: Algeria | B20: 2015 | C20: 68 | D20: 5.605 | E20: 0.93929 | F20: 1.07772 | G20: 0.61766 | H20: 0.28579 | I20: 0.07822 | J20: 0.17383 | K20: 1.7503198 | L20: 3.604882 | M20: -6.4556358 | N20: 4.3916664 | P20: 2.2497056 | Q20: Africa | S20: 0.29247 | T20: 0.067 | U20: 0.006 | W20: SORT
A21: Algeria | B21: 2016 | C21: 38 | D21: 6.355 | E21: 1.05266 | F21: 0.83309 | G21: 0.61804 | H21: 0.21006 | I21: 0.07044 | J21: 0.16157 | K21: 5.9810543 | L21: 2.6168447 | M21: 1.5487295 | N21: 5.8003039 | P21: 4.1193409 | Q21: Africa | S21: 0.29561 | T21: 0.07699 | U21: 0.00615
A22: Algeria | B22: 2017 | C22: 53 | D22: 5.8720002 | E22: 1.0918645 | F22: 1.1462175 | G22: 0.61758465 | H22: 0.23333581 | I22: 0.069436647 | J22: 0.14609611 | K22: 2.8017797 | L22: 5.6054001 | M22: 6.3908369 | N22: 5.591 | P22: 1.8786095 | Q22: Africa | S22: 0.30285 | T22: 0.077 | U22: 0.00649
A23: Algeria | B23: 2018 | C23: 84 | D23: 5.295 | E23: 0.979 | F23: 1.154 | G23: 0.687 | H23: 0.077 | I23: 0.055 | J23: 0.135 | K23: 1.2388263 | L23: 1.7412293 | M23: 7.0647866 | N23: 3.51 | P23: 4.0810566 | Q23: Africa | S23: 0.3109 | T23: 0.085 | U23: 0.00679
A24: Algeria | B24: 2019 | C24: 88 | D24: 5.211 | E24: 1.002 | F24: 1.16 | G24: 0.785 | H24: 0.086 | I24: 0.073 | J24: 0.114 | K24: 1.425144 | L24: 0.64319569 | M24: -0.90998946 | N24: 1.952 | P24: 2.6372888 | Q24: Africa | S24: 0.31945986 | T24: 0.086 | U24: 0.00872
A25: Algeria | B25: 2020 | C25: 100 | D25: 5.0050998 | E25: 0.943856 | F25: 0.80338514 | G25: 65.905174 | H25: 0.46661091 | I25: -0.12110516 | J25: 0.73548514 | K25: 1.3897383 | L25: 0.22050305 | M25: -4.6866948 | N25: 2.4151309 | Q25: Africa | S25: 0.322 | T25: 0.09245 | U25: 0.008964816
A26: Algeria | B26: 2021 | C26: 109 | D26: 4.887 | E26: 9.342 | F26: 0.802 | G26: 66.005 | H26: 0.48 | I26: -0.067 | J26: 0.752 | K26: 1.47 | L26: 10.13 | M26: 15.736744 | N26: 7.2260631 | P26: 7.4329045 | Q26: Africa | S26: 0.33613 | T26: 0.09511 | U26: 0.009
A27: Algeria | B27: 2022 | C27: 96 | D27: 5.122 | E27: 1.363 | F27: 0.97 | G27: 0.643 | H27: 0.146 | I27: 0.106 | J27: 0.15 | K27: 2.4020968 | L27: 12.7019 | M27: 15.567649 | N27: 9.2655155 | Q27: Africa | S27: 0.341 | T27: 0.095731251 | U27: 0.01
A28: Algeria | B28: 2023 | C28: 81 | D28: 5.329 | E28: 9.3 | F28: 0.855 | G28: 66.549 | H28: 0.571 | I28: -0.117 | J28: 0.717 | K28: 1.4879778 | L28: 13.256373 | M28: -0.42962924 | N28: 9.3221738 | Q28: Africa | S28: 0.35386 | T28: 0.096098043 | U28: 0.010091286
A29: Angola | B29: 2015 | C29: 137 | D29: 4.033 | E29: 0.75778 | F29: 0.8604 | G29: 0.16683 | H29: 0.10384 | I29: 0.12344 | J29: 0.07122 | L29: 9.2964697 | M29: -3.5183903 | N29: 9.1590004 | P29: 9.1711226 | Q29: Africa | S29: 0.372 | T29: 0.10081 | U29: 0.01031
A30: Angola | B30: 2016 | C30: 141 | D30: 3.866 | E30: 0.84731 | F30: 0.66366 | G30: 0.04991 | H30: 0.00589 | I30: 0.12071 | J30: 0.08434 | L30: 21.2355 | M30: 21.7743 | N30: 32.377731 | P30: 20.392229 | Q30: Africa | S30: 0.376 | T30: 0.103 | U30: 0.01078
A31: Angola | B31: 2017 | C31: 140 | D31: 3.7950001 | E31: 0.85842818 | F31: 1.104412 | G31: 0.049868666 | H31: 0 | I31: 0.09792649 | J31: 0.069720335 | L31: 40.986217 | M31: 22.617828 | N31: 29.844 | P31: 23.023481 | Q31: Africa | S31: 0.37932 | T31: 0.10384 | U31: 0.011
A32: Angola | B32: 2018 | C32: 142 | D32: 3.795 | E32: 0.73 | F32: 1.125 | G32: 0.269 | H32: 0 | I32: 0.079 | J32: 0.061 | L32: 22.350267 | M32: 33.762011 | N32: 19.63 | P32: 16.090868 | Q32: Africa | S32: 0.38174 | T32: 0.10617952 | U32: 0.011051531
A33: Argentina | B33: 2015 | C33: 30 | D33: 6.574 | E33: 1.05351 | F33: 1.24823 | G33: 0.78723 | H33: 0.44974 | I33: 0.11451 | J33: 0.08484 | M33: 26.579992 | N33: 26.538401 | Q33: South America | S33: 0.38562 | T33: 0.112 | U33: 0.0114
A34: Argentina | B34: 2016 | C34: 26 | D34: 6.65 | E34: 1.15137 | F34: 1.06612 | G34: 0.69711 | H34: 0.42284 | I34: 0.10989 | J34: 0.07296 | L34: 49.432299 | M34: 41.119381 | N34: 39.400002 | Q34: South America | S34: 0.38595 | T34: 0.1185 | U34: 0.011865643
A35: Argentina | B35: 2017 | C35: 24 | D35: 6.599 | E35: 1.1852955 | F35: 1.4404511 | G35: 0.69513708 | H35: 0.4945192 | I35: 0.10945706 | J35: 0.059739888 | L35: 20.36 | M35: 26.006378 | N35: 25.675 | P35: 16.26404 | Q35: South America | S35: 0.41134 | T35: 0.12072 | U35: 0.01241
A36: Argentina | B36: 2018 | C36: 29 | D36: 6.388 | E36: 1.073 | F36: 1.468 | G36: 0.744 | H36: 0.57 | I36: 0.062 | J36: 0.054 | K36: 52.759998 | L36: 32.738937 | M36: 40.012154 | N36: 34.28 | P36: 52.216434 | Q36: South America | S36: 0.413 | T36: 0.12102 | U36: 0.01397
A37: Argentina | B37: 2019 | C37: 47 | D37: 6.086 | E37: 1.092 | F37: 1.432 | G37: 0.881 | H37: 0.471 | I37: 0.066 | J37: 0.05 | K37: 49.280769 | L37: 58.344105 | M37: 50.622581 | N37: 53.548 | P37: 58.310783 | Q37: South America | S37: 0.41411 | T37: 0.12297478 | U37: 0.014
A38: Argentina | B38: 2020 | C38: 55 | D38: 5.9747 | E38: 1.0284656 | F38: 0.90056795 | G38: 68.803802 | H38: 0.83113241 | I38: -0.19491386 | J38: 0.84200984 | K38: 19.946911 | L38: 46.970287 | M38: 39.840848 | N38: 42.015095 | P38: 42.507 | Q38: South America | S38: 0.41587 | T38: 0.1268 | U38: 0.014
A39: Argentina | B39: 2021 | C39: 57 | D39: 5.929 | E39: 9.962 | F39: 0.898 | G39: 69 | H39: 0.828 | I39: -0.182 | J39: 0.834 | K39: 26.23 | L39: 49.846 | M39: 54.152412 | N39: 48.40938 | P39: 59.085495 | Q39: South America | S39: 0.416 | T39: 0.12807 | U39: 0.01521
A40: Argentina | B40: 2022 | C40: 57 | D40: 5.967 | E40: 1.592 | F40: 1.102 | G40: 0.662 | H40: 0.555 | I40: 0.081 | J40: 0.085 | K40: 51.398287 | L40: 74.63056 | M40: 41.066531 | N40: 72.43076 | P40: 60.273346 | Q40: South America | S40: 0.43106 | T40: 0.12859 | U40: 0.015317135
...

Sheet Аналітичні висновки

Sheet QQ
A1: SORT_Social support | B1: SORT_Freedom | C1: SORT_Corruption | D1: Rank | E1: Theoretical Quantiles | F1: Z-score
A2: {=SORT(Raw!F2:F1204)} -> 0 | B2: {=SORT(Raw!H2:H1204)} -> 0 | C2: {=SORT(Raw!J2:J1204)} -> 0 | D2: {=SEQUENCE(1203, 1, 1, 1)} -> 1 | E2: =(D2-0.5)/COUNT(D:D) -> 0.0004156276 | F2: =_xlfn.NORM.S.INV(E2) -> -3.342172
A3: 0 | B3: 0 | C3: 0 | D3: 2 | E3: =(D3-0.5)/COUNT(D:D) -> 0.0012468828 | F3: =_xlfn.NORM.S.INV(E3) -> -3.0240969
A4: 0 | B4: 0 | C4: 0 | D4: 3 | E4: =(D4-0.5)/COUNT(D:D) -> 0.002078138 | F4: =_xlfn.NORM.S.INV(E4) -> -2.8660508
A5: 0 | B5: 0 | C5: 0 | D5: 4 | E5: =(D5-0.5)/COUNT(D:D) -> 0.0029093932 | F5: =_xlfn.NORM.S.INV(E5) -> -2.7578221
A6: 0 | B6: 0 | C6: 0 | D6: 5 | E6: =(D6-0.5)/COUNT(D:D) -> 0.0037406484 | F6: =_xlfn.NORM.S.INV(E6) -> -2.6746246
A7: 0 | B7: 0 | C7: 0 | D7: 6 | E7: =(D7-0.5)/COUNT(D:D) -> 0.0045719036 | F7: =_xlfn.NORM.S.INV(E7) -> -2.6066301
A8: 0.064 | B8: 0.00589 | C8: 0 | D8: 7 | E8: =(D8-0.5)/COUNT(D:D) -> 0.0054031588 | F8: =_xlfn.NORM.S.INV(E8) -> -2.5489003
A9: 0.10419 | B9: 0.01 | C9: 0.001 | D9: 8 | E9: =(D9-0.5)/COUNT(D:D) -> 0.006234414 | F9: =_xlfn.NORM.S.INV(E9) -> -2.4985906
A10: 0.11037 | B10: 0.014995855 | C10: 0.00227 | D10: 9 | E10: =(D10-0.5)/COUNT(D:D) -> 0.0070656692 | F10: =_xlfn.NORM.S.INV(E10) -> -2.4539074
A11: 0.13995 | B11: 0.016 | C11: 0.00322 | D11: 10 | E11: =(D11-0.5)/COUNT(D:D) -> 0.0078969244 | F11: =_xlfn.NORM.S.INV(E11) -> -2.4136449
A12: 0.147 | B12: 0.025 | C12: 0.004 | D12: 11 | E12: =(D12-0.5)/COUNT(D:D) -> 0.0087281796 | F12: =_xlfn.NORM.S.INV(E12) -> -2.376952
A13: 0.18519 | B13: 0.026 | C13: 0.004387901 | D13: 12 | E13: =(D13-0.5)/COUNT(D:D) -> 0.0095594347 | F13: =_xlfn.NORM.S.INV(E13) -> -2.3432051
A14: 0.19249 | B14: 0.030369857 | C14: 0.005 | D14: 13 | E14: =(D14-0.5)/COUNT(D:D) -> 0.01039069 | F14: =_xlfn.NORM.S.INV(E14) -> -2.3119329
... A1203: 1.624 | B1203: 0.97 | C1203: 0.939 | D1203: 1202 | E1203: =(D1203-0.5)/COUNT(D:D) -> 0.99875312 | F1203: =_xlfn.NORM.S.INV(E1203) -> 3.0240969
A1204: 1.644 | B1204: 0.97499812 | D1204: 1203 | E1204: =(D1204-0.5)/COUNT(D:D) -> 0.99958437 | F1204: =_xlfn.NORM.S.INV(E1204) -> 3.342172

Sheet Distribution check
A1: Гістограми:
A19: Припущення: | F19: Припущення: | K19: Припущення:
A20: форма гістограми не схожа на дзвін і дані не є симетрично розподілені на графіку, тому припускаємо, що цей розподіл не є гаусівським. Хоча значення все ж скупчуються в центральній частині і утворюють пік, дуже віддалено таки є схожість з нормальним розподілом. Можливо, подальші обчислення вкажуть на це. Це може бути нормальним розподілом з асиметрією. | F20: тут форма гістограми також не схожа на дзвін і дані не є симетричними, тому припускаʼмо, що цей розподіл не є нормальним. Можливо тут розподіл рівномірний | K20: дані на гістограмі сильно зміщені в ліву частину і не є симетричними, тому припускаємо, що цей розподіл теж не є нормальним. Можливо, це експоненційний розподіл.
A28: QQ plot:
A46: Skewness | B46: =SKEW(Raw!F2:F1204) -> -0.10073856 | F46: Skewness | G46: =SKEW(Raw!H2:H1204) -> -0.11187636 | K46: Skewness | L46: =SKEW(Raw!J2:J1204) -> 0.741176
A47: Kurtosis | B47: =KURT(Raw!F2:F1204) -> -0.033933682 | F47: Kurtosis | G47: =KURT(Raw!H3:H1205) -> -0.60362942 | K47: Kurtosis | L47: =KURT(Raw!J3:J1205) -> -1.0984236
A49: Висновки: | F49: Висновки: | K49: Висновки:
A50: Більшість точок укладаються вздовж діагональної лінії - це характерно для нормального р-лу. Обрахуване значення Kurtosis близьке до 0 також саме при нормальному р-лі. Skewness показує практично симетричний розподіл. Підтверджує наші припущення. | F50: Знову більшість точок укладаються вздовж діагональної лінії як при нормальному р-лі. Значення Skewness близьке до 0 вказує на симетричність розподілу. Його відємність - це легка ліва асиметрія. Обрахуване значення Kurtosis -0,6 також наближене до нормального р-лу. Тож розподіл таки близький до нормального. Підтверджує наші припущення. | K50: Одразу помітна форма "S". Тут значення Skewness більше ніж 0,5 вказує на помірну асиметрію. Додатнє - отже наявна права асиметрія. Обраховане значення Kurtosis далеке від 0 - не є нормальним р-лом. Від'ємне - як і має бути при приплюсненій вершині. Отже ще раз - даний розподіл не є нормальним. Підтверджує наші припущення.
A58: розподіл Perceptions of corruption:
A59: На гістограмі спостерігаємо значну кількість малих значень в центральній частині, пласку форму. S-подібна форма на QQ-plot підтверджують припущення про експоненційний характер цього розподілу. Відмічаємо помірну праву асиметрію. Цей показник відображає сприйняття корупції в суспільстві, яке, за замовчанням, не може бути високим. Тому більшість значень в добірці даних є малими. Ніби це відображається в S-формі - розподіл із недостатньою дисперсією, що свідчить про нижчу варіативність.
